
#######################################################################
# +-----------------------------------------------------------------+ #
# |                            BO3 object                           | #
# +-----------------------------------------------------------------+ #
#######################################################################

Author: NLBlackEagle

Description: No description given

Version: 3

SettingsMode: WriteWithoutComments


#######################################################################
# +-----------------------------------------------------------------+ #
# |                          Main settings                          | #
# +-----------------------------------------------------------------+ #
#######################################################################

Tree: true

Frequency: 1

Rarity: 100.0

MaxSpawn: 0

RotateRandomly: false

SpawnHeight: highestBlock

SpawnHeightOffset: -27

SpawnHeightVariance: 0

##############################
# Height Limits for the BO3. #
##############################

MinHeight: 0

MaxHeight: 255

######################
# Extrusion settings #
######################

ExtrudeMode: None

ExtrudeThroughBlocks: otg:air

MaxBranchDepth: 10


#######################################################################
# +-----------------------------------------------------------------+ #
# |                      Source block settings                      | #
# +-----------------------------------------------------------------+ #
#######################################################################

SourceBlocks: otg:stone,otg:dirt,minecraft:obsidian,minecraft:grass_block,minecraft:coal_ore

MaxPercentageOutsideSourceBlock: 47

OutsideSourceBlock: placeAnyway

DoReplaceBlocks: true

IsOTGPlus: false


#######################################################################
# +-----------------------------------------------------------------+ #
# |                              Blocks                             | #
# +-----------------------------------------------------------------+ #
#######################################################################

B(-15,22,-11,minecraft:grass_block)
B(-15,22,-10,minecraft:grass_block)
B(-15,22,-9,minecraft:grass_block)
B(-15,22,-8,minecraft:grass_block)
B(-15,22,-7,minecraft:stone)
B(-15,22,-6,minecraft:stone)
B(-15,22,-5,minecraft:stone)
B(-15,22,-4,minecraft:stone)
B(-15,22,-3,minecraft:stone)
B(-15,22,-2,minecraft:stone)
B(-15,22,-1,minecraft:stone)
B(-15,22,0,minecraft:grass_block)
B(-15,22,1,minecraft:grass_block)
B(-15,22,2,minecraft:grass_block)
B(-15,22,3,minecraft:grass_block)
B(-15,22,4,minecraft:grass_block)
B(-15,22,5,minecraft:grass_block)
B(-15,22,6,minecraft:stone)
B(-15,22,7,minecraft:stone)
B(-15,22,8,minecraft:stone)
B(-15,22,9,minecraft:stone)
B(-15,22,10,minecraft:grass_block)
B(-15,22,11,minecraft:grass_block)
B(-15,22,12,minecraft:grass_block)
B(-15,23,-7,minecraft:stone)
B(-15,23,-6,minecraft:stone)
B(-15,23,-5,minecraft:stone)
B(-15,23,-4,minecraft:stone)
B(-15,23,-3,minecraft:stone)
B(-15,23,-2,minecraft:stone)
B(-15,23,-1,minecraft:stone)
B(-15,23,6,minecraft:grass_block)
B(-15,23,7,minecraft:stone)
B(-15,23,8,minecraft:grass_block)
B(-15,23,9,minecraft:grass_block)
B(-15,24,-7,minecraft:grass_block)
B(-15,24,-6,minecraft:stone)
B(-15,24,-5,minecraft:stone)
B(-15,24,-4,minecraft:stone)
B(-15,24,-3,minecraft:stone)
B(-15,24,-2,minecraft:stone)
B(-15,24,-1,minecraft:grass_block)
B(-15,24,7,minecraft:grass_block)
B(-15,25,-6,minecraft:stone)
B(-15,25,-5,minecraft:stone)
B(-15,25,-4,minecraft:stone)
B(-15,25,-3,minecraft:grass_block)
B(-15,25,-2,minecraft:stone)
B(-15,26,-6,minecraft:grass_block)
B(-15,26,-5,minecraft:stone)
B(-15,26,-4,minecraft:grass_block)
B(-15,26,-2,minecraft:grass_block)
B(-15,27,-5,minecraft:grass_block)
B(-14,22,-11,minecraft:grass_block)
B(-14,22,-10,minecraft:grass_block)
B(-14,22,-9,minecraft:grass_block)
B(-14,22,-8,minecraft:grass_block)
B(-14,22,-7,minecraft:stone)
B(-14,22,-6,minecraft:stone)
B(-14,22,-5,minecraft:stone)
B(-14,22,-4,minecraft:stone)
B(-14,22,-3,minecraft:stone)
B(-14,22,-2,minecraft:stone)
B(-14,22,-1,minecraft:stone)
B(-14,22,0,minecraft:stone)
B(-14,22,1,minecraft:stone)
B(-14,22,2,minecraft:stone)
B(-14,22,3,minecraft:grass_block)
B(-14,22,4,minecraft:grass_block)
B(-14,22,5,minecraft:stone)
B(-14,22,6,minecraft:stone)
B(-14,22,7,minecraft:stone)
B(-14,22,8,minecraft:stone)
B(-14,22,9,minecraft:stone)
B(-14,22,10,minecraft:stone)
B(-14,22,11,minecraft:stone)
B(-14,22,12,minecraft:grass_block)
B(-14,23,-7,minecraft:stone)
B(-14,23,-6,minecraft:stone)
B(-14,23,-5,minecraft:stone)
B(-14,23,-4,minecraft:stone)
B(-14,23,-3,minecraft:stone)
B(-14,23,-2,minecraft:stone)
B(-14,23,-1,minecraft:stone)
B(-14,23,0,minecraft:stone)
B(-14,23,1,minecraft:grass_block)
B(-14,23,2,minecraft:grass_block)
B(-14,23,5,minecraft:grass_block)
B(-14,23,6,minecraft:stone)
B(-14,23,7,minecraft:stone)
B(-14,23,8,minecraft:grass_block)
B(-14,23,9,minecraft:stone)
B(-14,23,10,minecraft:stone)
B(-14,23,11,minecraft:stone)
B(-14,24,-7,minecraft:stone)
B(-14,24,-6,minecraft:stone)
B(-14,24,-5,minecraft:stone)
B(-14,24,-4,minecraft:stone)
B(-14,24,-3,minecraft:stone)
B(-14,24,-2,minecraft:stone)
B(-14,24,-1,minecraft:stone)
B(-14,24,0,minecraft:grass_block)
B(-14,24,6,minecraft:grass_block)
B(-14,24,7,minecraft:stone)
B(-14,24,9,minecraft:grass_block)
B(-14,24,10,minecraft:stone)
B(-14,24,11,minecraft:grass_block)
B(-14,25,-7,minecraft:grass_block)
B(-14,25,-6,minecraft:stone)
B(-14,25,-5,minecraft:stone)
B(-14,25,-4,minecraft:stone)
B(-14,25,-3,minecraft:stone)
B(-14,25,-2,minecraft:stone)
B(-14,25,-1,minecraft:grass_block)
B(-14,25,7,minecraft:stone)
B(-14,25,10,minecraft:grass_block)
B(-14,26,-6,minecraft:stone)
B(-14,26,-5,minecraft:stone)
B(-14,26,-4,minecraft:stone)
B(-14,26,-3,minecraft:stone)
B(-14,26,-2,minecraft:stone)
B(-14,26,7,minecraft:grass_block)
B(-14,27,-6,minecraft:grass_block)
B(-14,27,-5,minecraft:stone)
B(-14,27,-4,minecraft:stone)
B(-14,27,-3,minecraft:grass_block)
B(-14,27,-2,minecraft:grass_block)
B(-14,28,-5,minecraft:stone)
B(-14,28,-4,minecraft:grass_block)
B(-14,29,-5,minecraft:grass_block)
B(-13,22,-11,minecraft:grass_block)
B(-13,22,-10,minecraft:grass_block)
B(-13,22,-9,minecraft:grass_block)
B(-13,22,-8,minecraft:stone)
B(-13,22,-7,minecraft:stone)
B(-13,22,-6,minecraft:stone)
B(-13,22,-5,minecraft:stone)
B(-13,22,-4,minecraft:stone)
B(-13,22,-3,minecraft:stone)
B(-13,22,-2,minecraft:stone)
B(-13,22,-1,minecraft:stone)
B(-13,22,0,minecraft:stone)
B(-13,22,1,minecraft:stone)
B(-13,22,2,minecraft:stone)
B(-13,22,3,minecraft:stone)
B(-13,22,4,minecraft:stone)
B(-13,22,5,minecraft:stone)
B(-13,22,6,minecraft:stone)
B(-13,22,7,minecraft:stone)
B(-13,22,8,minecraft:stone)
B(-13,22,9,minecraft:stone)
B(-13,22,10,minecraft:stone)
B(-13,22,11,minecraft:stone)
B(-13,22,12,minecraft:grass_block)
B(-13,23,-8,minecraft:stone)
B(-13,23,-7,minecraft:stone)
B(-13,23,-6,minecraft:stone)
B(-13,23,-5,minecraft:stone)
B(-13,23,-4,minecraft:stone)
B(-13,23,-3,minecraft:stone)
B(-13,23,-2,minecraft:stone)
B(-13,23,-1,minecraft:stone)
B(-13,23,0,minecraft:stone)
B(-13,23,1,minecraft:stone)
B(-13,23,2,minecraft:stone)
B(-13,23,3,minecraft:stone)
B(-13,23,4,minecraft:grass_block)
B(-13,23,5,minecraft:grass_block)
B(-13,23,6,minecraft:stone)
B(-13,23,7,minecraft:stone)
B(-13,23,8,minecraft:stone)
B(-13,23,9,minecraft:stone)
B(-13,23,10,minecraft:stone)
B(-13,23,11,minecraft:stone)
B(-13,24,-8,minecraft:grass_block)
B(-13,24,-7,minecraft:stone)
B(-13,24,-6,minecraft:stone)
B(-13,24,-5,minecraft:stone)
B(-13,24,-4,minecraft:stone)
B(-13,24,-3,minecraft:stone)
B(-13,24,-2,minecraft:stone)
B(-13,24,-1,minecraft:stone)
B(-13,24,0,minecraft:stone)
B(-13,24,1,minecraft:stone)
B(-13,24,2,minecraft:stone)
B(-13,24,3,minecraft:grass_block)
B(-13,24,6,minecraft:stone)
B(-13,24,7,minecraft:stone)
B(-13,24,8,minecraft:stone)
B(-13,24,9,minecraft:stone)
B(-13,24,10,minecraft:stone)
B(-13,24,11,minecraft:stone)
B(-13,25,-7,minecraft:stone)
B(-13,25,-6,minecraft:stone)
B(-13,25,-5,minecraft:stone)
B(-13,25,-4,minecraft:stone)
B(-13,25,-3,minecraft:stone)
B(-13,25,-2,minecraft:stone)
B(-13,25,-1,minecraft:stone)
B(-13,25,0,minecraft:stone)
B(-13,25,1,minecraft:stone)
B(-13,25,2,minecraft:grass_block)
B(-13,25,6,minecraft:stone)
B(-13,25,7,minecraft:stone)
B(-13,25,8,minecraft:stone)
B(-13,25,9,minecraft:stone)
B(-13,25,10,minecraft:stone)
B(-13,25,11,minecraft:stone)
B(-13,26,-7,minecraft:stone)
B(-13,26,-6,minecraft:stone)
B(-13,26,-5,minecraft:stone)
B(-13,26,-4,minecraft:stone)
B(-13,26,-3,minecraft:stone)
B(-13,26,-2,minecraft:stone)
B(-13,26,-1,minecraft:grass_block)
B(-13,26,0,minecraft:stone)
B(-13,26,1,minecraft:grass_block)
B(-13,26,6,minecraft:stone)
B(-13,26,7,minecraft:stone)
B(-13,26,8,minecraft:stone)
B(-13,26,9,minecraft:stone)
B(-13,26,10,minecraft:grass_block)
B(-13,26,11,minecraft:grass_block)
B(-13,27,-7,minecraft:grass_block)
B(-13,27,-6,minecraft:stone)
B(-13,27,-5,minecraft:stone)
B(-13,27,-4,minecraft:stone)
B(-13,27,-3,minecraft:stone)
B(-13,27,-2,minecraft:stone)
B(-13,27,0,minecraft:grass_block)
B(-13,27,6,minecraft:grass_block)
B(-13,27,7,minecraft:stone)
B(-13,27,8,minecraft:grass_block)
B(-13,27,9,minecraft:grass_block)
B(-13,28,-6,minecraft:grass_block)
B(-13,28,-5,minecraft:grass_block)
B(-13,28,-4,minecraft:stone)
B(-13,28,-3,minecraft:grass_block)
B(-13,28,-2,minecraft:grass_block)
B(-13,28,7,minecraft:grass_block)
B(-13,29,-4,minecraft:grass_block)
B(-12,21,-4,minecraft:stone)
B(-12,21,-3,minecraft:stone)
B(-12,21,-2,minecraft:stone)
B(-12,21,-1,minecraft:stone)
B(-12,21,0,minecraft:stone)
B(-12,21,1,minecraft:stone)
B(-12,21,2,minecraft:stone)
B(-12,22,-11,minecraft:grass_block)
B(-12,22,-10,minecraft:grass_block)
B(-12,22,-9,minecraft:stone)
B(-12,22,-8,minecraft:stone)
B(-12,22,-7,minecraft:stone)
B(-12,22,-6,minecraft:stone)
B(-12,22,-5,minecraft:stone)
B(-12,22,-4,minecraft:oak_fence)
B(-12,22,-3,minecraft:oak_fence)
B(-12,22,-2,minecraft:stone)
B(-12,22,-1,minecraft:spruce_log)
B(-12,22,0,minecraft:stone)
B(-12,22,1,minecraft:stone)
B(-12,22,2,minecraft:oak_fence)
B(-12,22,3,minecraft:stone)
B(-12,22,4,minecraft:stone)
B(-12,22,5,minecraft:stone)
B(-12,22,6,minecraft:stone)
B(-12,22,7,minecraft:stone)
B(-12,22,8,minecraft:stone)
B(-12,22,9,minecraft:stone)
B(-12,22,10,minecraft:stone)
B(-12,22,11,minecraft:stone)
B(-12,22,12,minecraft:grass_block)
B(-12,23,-9,minecraft:grass_block)
B(-12,23,-8,minecraft:stone)
B(-12,23,-7,minecraft:stone)
B(-12,23,-6,minecraft:stone)
B(-12,23,-5,minecraft:stone)
B(-12,23,-4,minecraft:oak_fence)
B(-12,23,-3,minecraft:stone)
B(-12,23,-2,minecraft:stone)
B(-12,23,-1,minecraft:spruce_log)
B(-12,23,0,minecraft:oak_fence)
B(-12,23,1,minecraft:stone)
B(-12,23,2,minecraft:oak_fence)
B(-12,23,3,minecraft:stone)
B(-12,23,4,minecraft:stone)
B(-12,23,5,minecraft:stone)
B(-12,23,6,minecraft:stone)
B(-12,23,7,minecraft:stone)
B(-12,23,8,minecraft:stone)
B(-12,23,9,minecraft:stone)
B(-12,23,10,minecraft:stone)
B(-12,23,11,minecraft:stone)
B(-12,24,-8,minecraft:stone)
B(-12,24,-7,minecraft:stone)
B(-12,24,-6,minecraft:stone)
B(-12,24,-5,minecraft:stone)
B(-12,24,-4,minecraft:stone)
B(-12,24,-3,minecraft:stone)
B(-12,24,-2,minecraft:stone)
B(-12,24,-1,minecraft:spruce_log)
B(-12,24,0,minecraft:oak_fence)
B(-12,24,1,minecraft:stone)
B(-12,24,2,minecraft:stone)
B(-12,24,3,minecraft:stone)
B(-12,24,4,minecraft:stone)
B(-12,24,5,minecraft:stone)
B(-12,24,6,minecraft:stone)
B(-12,24,7,minecraft:stone)
B(-12,24,8,minecraft:stone)
B(-12,24,9,minecraft:stone)
B(-12,24,10,minecraft:stone)
B(-12,24,11,minecraft:grass_block)
B(-12,25,-8,minecraft:stone)
B(-12,25,-7,minecraft:stone)
B(-12,25,-6,minecraft:stone)
B(-12,25,-5,minecraft:stone)
B(-12,25,-4,minecraft:stone)
B(-12,25,-3,minecraft:stone)
B(-12,25,-2,minecraft:stone)
B(-12,25,-1,minecraft:stone)
B(-12,25,0,minecraft:stone)
B(-12,25,1,minecraft:stone)
B(-12,25,2,minecraft:stone)
B(-12,25,3,minecraft:stone)
B(-12,25,4,minecraft:stone)
B(-12,25,5,minecraft:grass_block)
B(-12,25,6,minecraft:stone)
B(-12,25,7,minecraft:stone)
B(-12,25,8,minecraft:stone)
B(-12,25,9,minecraft:stone)
B(-12,25,10,minecraft:stone)
B(-12,26,-8,minecraft:grass_block)
B(-12,26,-7,minecraft:stone)
B(-12,26,-6,minecraft:stone)
B(-12,26,-5,minecraft:stone)
B(-12,26,-4,minecraft:stone)
B(-12,26,-3,minecraft:stone)
B(-12,26,-2,minecraft:stone)
B(-12,26,-1,minecraft:stone)
B(-12,26,0,minecraft:stone)
B(-12,26,1,minecraft:stone)
B(-12,26,2,minecraft:stone)
B(-12,26,3,minecraft:stone)
B(-12,26,4,minecraft:grass_block)
B(-12,26,6,minecraft:stone)
B(-12,26,7,minecraft:stone)
B(-12,26,8,minecraft:stone)
B(-12,26,9,minecraft:stone)
B(-12,26,10,minecraft:stone)
B(-12,27,-7,minecraft:grass_block)
B(-12,27,-6,minecraft:stone)
B(-12,27,-5,minecraft:stone)
B(-12,27,-4,minecraft:stone)
B(-12,27,-3,minecraft:stone)
B(-12,27,-2,minecraft:stone)
B(-12,27,-1,minecraft:stone)
B(-12,27,0,minecraft:stone)
B(-12,27,1,minecraft:grass_block)
B(-12,27,2,minecraft:grass_block)
B(-12,27,3,minecraft:grass_block)
B(-12,27,6,minecraft:stone)
B(-12,27,7,minecraft:stone)
B(-12,27,8,minecraft:stone)
B(-12,27,9,minecraft:stone)
B(-12,27,10,minecraft:grass_block)
B(-12,28,-6,minecraft:grass_block)
B(-12,28,-5,minecraft:stone)
B(-12,28,-4,minecraft:stone)
B(-12,28,-3,minecraft:stone)
B(-12,28,-2,minecraft:stone)
B(-12,28,-1,minecraft:stone)
B(-12,28,0,minecraft:grass_block)
B(-12,28,6,minecraft:stone)
B(-12,28,7,minecraft:stone)
B(-12,28,8,minecraft:stone)
B(-12,28,9,minecraft:grass_block)
B(-12,29,-5,minecraft:grass_block)
B(-12,29,-4,minecraft:stone)
B(-12,29,-3,minecraft:grass_block)
B(-12,29,-2,minecraft:stone)
B(-12,29,-1,minecraft:grass_block)
B(-12,29,6,minecraft:grass_block)
B(-12,29,7,minecraft:grass_block)
B(-12,29,8,minecraft:grass_block)
B(-12,30,-4,minecraft:grass_block)
B(-12,30,-2,minecraft:grass_block)
B(-11,21,-5,minecraft:stone)
B(-11,21,-4,minecraft:stone)
B(-11,21,-3,minecraft:stone)
B(-11,21,-2,minecraft:stone)
B(-11,21,-1,minecraft:stone)
B(-11,21,0,minecraft:stone)
B(-11,21,1,minecraft:stone)
B(-11,21,2,minecraft:stone)
B(-11,22,-11,minecraft:grass_block)
B(-11,22,-10,minecraft:grass_block)
B(-11,22,-9,minecraft:stone)
B(-11,22,-8,minecraft:stone)
B(-11,22,-7,minecraft:stone)
B(-11,22,-6,minecraft:stone)
B(-11,22,-5,minecraft:oak_fence)
B(-11,22,-4,minecraft:rail[shape=south_east])
B(-11,22,-3,minecraft:rail)
B(-11,22,-2,minecraft:rail)
B(-11,22,-1,minecraft:rail)
B(-11,22,0,minecraft:rail)
B(-11,22,1,minecraft:rail)
B(-11,22,2,minecraft:rail[shape=north_east])
B(-11,22,3,minecraft:stone)
B(-11,22,4,minecraft:stone)
B(-11,22,5,minecraft:stone)
B(-11,22,6,minecraft:stone)
B(-11,22,7,minecraft:stone)
B(-11,22,8,minecraft:stone)
B(-11,22,9,minecraft:stone)
B(-11,22,10,minecraft:stone)
B(-11,22,11,minecraft:stone)
B(-11,22,12,minecraft:grass_block)
B(-11,23,-9,minecraft:stone)
B(-11,23,-8,minecraft:stone)
B(-11,23,-7,minecraft:stone)
B(-11,23,-6,minecraft:stone)
B(-11,23,-5,minecraft:oak_fence)
B(-11,23,-4,minecraft:air)
B(-11,23,-3,minecraft:air)
B(-11,23,-2,minecraft:air)
B(-11,23,-1,minecraft:air)
B(-11,23,0,minecraft:air)
B(-11,23,1,minecraft:air)
B(-11,23,2,minecraft:air)
B(-11,23,3,minecraft:oak_fence)
B(-11,23,4,minecraft:stone)
B(-11,23,5,minecraft:stone)
B(-11,23,6,minecraft:stone)
B(-11,23,7,minecraft:stone)
B(-11,23,8,minecraft:stone)
B(-11,23,9,minecraft:stone)
B(-11,23,10,minecraft:stone)
B(-11,23,11,minecraft:stone)
B(-11,24,-9,minecraft:grass_block)
B(-11,24,-8,minecraft:stone)
B(-11,24,-7,minecraft:stone)
B(-11,24,-6,minecraft:stone)
B(-11,24,-5,minecraft:oak_fence)
B(-11,24,-4,minecraft:air)
B(-11,24,-3,minecraft:air)
B(-11,24,-2,minecraft:air)
B(-11,24,-1,minecraft:air)
B(-11,24,0,minecraft:air)
B(-11,24,1,minecraft:air)
B(-11,24,2,minecraft:air)
B(-11,24,3,minecraft:oak_fence)
B(-11,24,4,minecraft:stone)
B(-11,24,5,minecraft:stone)
B(-11,24,6,minecraft:stone)
B(-11,24,7,minecraft:stone)
B(-11,24,8,minecraft:stone)
B(-11,24,9,minecraft:stone)
B(-11,24,10,minecraft:stone)
B(-11,24,11,minecraft:stone)
B(-11,25,-8,minecraft:grass_block)
B(-11,25,-7,minecraft:stone)
B(-11,25,-6,minecraft:stone)
B(-11,25,-5,minecraft:stone)
B(-11,25,-4,minecraft:stone)
B(-11,25,-3,minecraft:stone)
B(-11,25,-2,minecraft:stone)
B(-11,25,-1,minecraft:spruce_log[axis=x])
B(-11,25,0,minecraft:stone)
B(-11,25,1,minecraft:stone)
B(-11,25,2,minecraft:stone)
B(-11,25,3,minecraft:stone)
B(-11,25,4,minecraft:stone)
B(-11,25,5,minecraft:stone)
B(-11,25,6,minecraft:stone)
B(-11,25,7,minecraft:stone)
B(-11,25,8,minecraft:stone)
B(-11,25,9,minecraft:stone)
B(-11,25,10,minecraft:stone)
B(-11,25,11,minecraft:grass_block)
B(-11,26,-7,minecraft:stone)
B(-11,26,-6,minecraft:stone)
B(-11,26,-5,minecraft:stone)
B(-11,26,-4,minecraft:stone)
B(-11,26,-3,minecraft:stone)
B(-11,26,-2,minecraft:stone)
B(-11,26,-1,minecraft:stone)
B(-11,26,0,minecraft:stone)
B(-11,26,1,minecraft:stone)
B(-11,26,2,minecraft:stone)
B(-11,26,3,minecraft:stone)
B(-11,26,4,minecraft:stone)
B(-11,26,5,minecraft:stone)
B(-11,26,6,minecraft:stone)
B(-11,26,7,minecraft:stone)
B(-11,26,8,minecraft:stone)
B(-11,26,9,minecraft:stone)
B(-11,26,10,minecraft:stone)
B(-11,27,-7,minecraft:grass_block)
B(-11,27,-6,minecraft:stone)
B(-11,27,-5,minecraft:stone)
B(-11,27,-4,minecraft:stone)
B(-11,27,-3,minecraft:stone)
B(-11,27,-2,minecraft:stone)
B(-11,27,-1,minecraft:stone)
B(-11,27,0,minecraft:stone)
B(-11,27,1,minecraft:stone)
B(-11,27,2,minecraft:stone)
B(-11,27,3,minecraft:stone)
B(-11,27,4,minecraft:stone)
B(-11,27,5,minecraft:grass_block)
B(-11,27,6,minecraft:stone)
B(-11,27,7,minecraft:stone)
B(-11,27,8,minecraft:stone)
B(-11,27,9,minecraft:stone)
B(-11,27,10,minecraft:stone)
B(-11,28,-6,minecraft:stone)
B(-11,28,-5,minecraft:stone)
B(-11,28,-4,minecraft:stone)
B(-11,28,-3,minecraft:stone)
B(-11,28,-2,minecraft:stone)
B(-11,28,-1,minecraft:stone)
B(-11,28,0,minecraft:stone)
B(-11,28,1,minecraft:grass_block)
B(-11,28,2,minecraft:stone)
B(-11,28,3,minecraft:stone)
B(-11,28,4,minecraft:grass_block)
B(-11,28,6,minecraft:stone)
B(-11,28,7,minecraft:stone)
B(-11,28,8,minecraft:stone)
B(-11,28,9,minecraft:stone)
B(-11,28,10,minecraft:grass_block)
B(-11,29,-6,minecraft:grass_block)
B(-11,29,-5,minecraft:stone)
B(-11,29,-4,minecraft:stone)
B(-11,29,-3,minecraft:stone)
B(-11,29,-2,minecraft:stone)
B(-11,29,-1,minecraft:stone)
B(-11,29,0,minecraft:grass_block)
B(-11,29,2,minecraft:grass_block)
B(-11,29,3,minecraft:grass_block)
B(-11,29,6,minecraft:stone)
B(-11,29,7,minecraft:stone)
B(-11,29,8,minecraft:stone)
B(-11,29,9,minecraft:grass_block)
B(-11,30,-5,minecraft:grass_block)
B(-11,30,-4,minecraft:grass_block)
B(-11,30,-3,minecraft:grass_block)
B(-11,30,-2,minecraft:stone)
B(-11,30,-1,minecraft:grass_block)
B(-11,30,6,minecraft:grass_block)
B(-11,30,7,minecraft:grass_block)
B(-11,30,8,minecraft:grass_block)
B(-11,31,-2,minecraft:grass_block)
B(-10,21,-5,minecraft:spruce_log[axis=x])
B(-10,21,-4,minecraft:stone)
B(-10,21,-3,minecraft:stone)
B(-10,21,-2,minecraft:stone)
B(-10,21,-1,minecraft:spruce_log[axis=x])
B(-10,21,0,minecraft:stone)
B(-10,21,1,minecraft:stone)
B(-10,21,2,minecraft:stone)
B(-10,22,-11,minecraft:grass_block)
B(-10,22,-10,minecraft:grass_block)
B(-10,22,-9,minecraft:stone)
B(-10,22,-8,minecraft:stone)
B(-10,22,-7,minecraft:stone)
B(-10,22,-6,minecraft:stone)
B(-10,22,-5,minecraft:stone)
B(-10,22,-4,minecraft:rail[shape=east_west])
B(-10,22,-3,minecraft:cobblestone_slab)
B(-10,22,-2,minecraft:cobblestone_slab)
B(-10,22,-1,minecraft:cobblestone_slab)
B(-10,22,0,minecraft:cobblestone_slab)
B(-10,22,1,minecraft:cobblestone_slab)
B(-10,22,2,minecraft:rail[shape=east_west])
B(-10,22,3,minecraft:oak_fence)
B(-10,22,4,minecraft:stone)
B(-10,22,5,minecraft:stone)
B(-10,22,6,minecraft:stone)
B(-10,22,7,minecraft:stone)
B(-10,22,8,minecraft:stone)
B(-10,22,9,minecraft:stone)
B(-10,22,10,minecraft:stone)
B(-10,22,11,minecraft:grass_block)
B(-10,22,12,minecraft:grass_block)
B(-10,23,-9,minecraft:stone)
B(-10,23,-8,minecraft:stone)
B(-10,23,-7,minecraft:stone)
B(-10,23,-6,minecraft:stone)
B(-10,23,-5,minecraft:stone)
B(-10,23,-4,minecraft:air)
B(-10,23,-3,minecraft:air)
B(-10,23,-2,minecraft:air)
B(-10,23,-1,minecraft:air)
B(-10,23,0,minecraft:air)
B(-10,23,1,minecraft:air)
B(-10,23,2,minecraft:air)
B(-10,23,3,minecraft:oak_fence)
B(-10,23,4,minecraft:stone)
B(-10,23,5,minecraft:stone)
B(-10,23,6,minecraft:stone)
B(-10,23,7,minecraft:stone)
B(-10,23,8,minecraft:stone)
B(-10,23,9,minecraft:stone)
B(-10,23,10,minecraft:stone)
B(-10,24,-9,minecraft:stone)
B(-10,24,-8,minecraft:stone)
B(-10,24,-7,minecraft:stone)
B(-10,24,-6,minecraft:stone)
B(-10,24,-5,minecraft:oak_fence)
B(-10,24,-4,minecraft:air)
B(-10,24,-3,minecraft:air)
B(-10,24,-2,minecraft:air)
B(-10,24,-1,minecraft:air)
B(-10,24,0,minecraft:air)
B(-10,24,1,minecraft:air)
B(-10,24,2,minecraft:air)
B(-10,24,3,minecraft:stone)
B(-10,24,4,minecraft:stone)
B(-10,24,5,minecraft:stone)
B(-10,24,6,minecraft:stone)
B(-10,24,7,minecraft:stone)
B(-10,24,8,minecraft:stone)
B(-10,24,9,minecraft:stone)
B(-10,24,10,minecraft:stone)
B(-10,25,-9,minecraft:grass_block)
B(-10,25,-8,minecraft:stone)
B(-10,25,-7,minecraft:stone)
B(-10,25,-6,minecraft:stone)
B(-10,25,-5,minecraft:stone)
B(-10,25,-4,minecraft:stone)
B(-10,25,-3,minecraft:stone)
B(-10,25,-2,minecraft:stone)
B(-10,25,-1,minecraft:spruce_log[axis=x])
B(-10,25,0,minecraft:stone)
B(-10,25,1,minecraft:stone)
B(-10,25,2,minecraft:stone)
B(-10,25,3,minecraft:stone)
B(-10,25,4,minecraft:stone)
B(-10,25,5,minecraft:stone)
B(-10,25,6,minecraft:stone)
B(-10,25,7,minecraft:stone)
B(-10,25,8,minecraft:stone)
B(-10,25,9,minecraft:stone)
B(-10,25,10,minecraft:stone)
B(-10,26,-8,minecraft:stone)
B(-10,26,-7,minecraft:stone)
B(-10,26,-6,minecraft:stone)
B(-10,26,-5,minecraft:stone)
B(-10,26,-4,minecraft:stone)
B(-10,26,-3,minecraft:stone)
B(-10,26,-2,minecraft:stone)
B(-10,26,-1,minecraft:stone)
B(-10,26,0,minecraft:stone)
B(-10,26,1,minecraft:stone)
B(-10,26,2,minecraft:stone)
B(-10,26,3,minecraft:stone)
B(-10,26,4,minecraft:stone)
B(-10,26,5,minecraft:stone)
B(-10,26,6,minecraft:stone)
B(-10,26,7,minecraft:stone)
B(-10,26,8,minecraft:stone)
B(-10,26,9,minecraft:stone)
B(-10,26,10,minecraft:stone)
B(-10,27,-8,minecraft:grass_block)
B(-10,27,-7,minecraft:stone)
B(-10,27,-6,minecraft:stone)
B(-10,27,-5,minecraft:stone)
B(-10,27,-4,minecraft:stone)
B(-10,27,-3,minecraft:stone)
B(-10,27,-2,minecraft:stone)
B(-10,27,-1,minecraft:stone)
B(-10,27,0,minecraft:stone)
B(-10,27,1,minecraft:stone)
B(-10,27,2,minecraft:stone)
B(-10,27,3,minecraft:stone)
B(-10,27,4,minecraft:stone)
B(-10,27,5,minecraft:stone)
B(-10,27,6,minecraft:stone)
B(-10,27,7,minecraft:stone)
B(-10,27,8,minecraft:stone)
B(-10,27,9,minecraft:stone)
B(-10,27,10,minecraft:grass_block)
B(-10,28,-7,minecraft:grass_block)
B(-10,28,-6,minecraft:stone)
B(-10,28,-5,minecraft:stone)
B(-10,28,-4,minecraft:stone)
B(-10,28,-3,minecraft:stone)
B(-10,28,-2,minecraft:stone)
B(-10,28,-1,minecraft:stone)
B(-10,28,0,minecraft:stone)
B(-10,28,1,minecraft:stone)
B(-10,28,2,minecraft:stone)
B(-10,28,3,minecraft:stone)
B(-10,28,4,minecraft:stone)
B(-10,28,5,minecraft:stone)
B(-10,28,6,minecraft:stone)
B(-10,28,7,minecraft:stone)
B(-10,28,8,minecraft:stone)
B(-10,28,9,minecraft:grass_block)
B(-10,29,-6,minecraft:stone)
B(-10,29,-5,minecraft:stone)
B(-10,29,-4,minecraft:stone)
B(-10,29,-3,minecraft:stone)
B(-10,29,-2,minecraft:stone)
B(-10,29,-1,minecraft:stone)
B(-10,29,0,minecraft:stone)
B(-10,29,1,minecraft:stone)
B(-10,29,2,minecraft:grass_block)
B(-10,29,3,minecraft:grass_block)
B(-10,29,4,minecraft:grass_block)
B(-10,29,5,minecraft:stone)
B(-10,29,6,minecraft:stone)
B(-10,29,7,minecraft:stone)
B(-10,29,8,minecraft:stone)
B(-10,30,-6,minecraft:stone)
B(-10,30,-5,minecraft:stone)
B(-10,30,-4,minecraft:stone)
B(-10,30,-3,minecraft:stone)
B(-10,30,-2,minecraft:stone)
B(-10,30,-1,minecraft:stone)
B(-10,30,0,minecraft:stone)
B(-10,30,1,minecraft:grass_block)
B(-10,30,5,minecraft:grass_block)
B(-10,30,6,minecraft:stone)
B(-10,30,7,minecraft:stone)
B(-10,30,8,minecraft:grass_block)
B(-10,31,-6,minecraft:grass_block)
B(-10,31,-5,minecraft:grass_block)
B(-10,31,-4,minecraft:grass_block)
B(-10,31,-3,minecraft:grass_block)
B(-10,31,-2,minecraft:grass_block)
B(-10,31,-1,minecraft:grass_block)
B(-10,31,0,minecraft:grass_block)
B(-10,31,6,minecraft:grass_block)
B(-10,31,7,minecraft:grass_block)
B(-9,21,-5,minecraft:spruce_log[axis=x])
B(-9,21,-4,minecraft:stone)
B(-9,21,-3,minecraft:stone)
B(-9,21,-2,minecraft:stone)
B(-9,21,-1,minecraft:spruce_log[axis=x])
B(-9,21,0,minecraft:stone)
B(-9,21,1,minecraft:stone)
B(-9,21,2,minecraft:stone)
B(-9,22,-11,minecraft:grass_block)
B(-9,22,-10,minecraft:stone)
B(-9,22,-9,minecraft:stone)
B(-9,22,-8,minecraft:stone)
B(-9,22,-7,minecraft:stone)
B(-9,22,-6,minecraft:stone)
B(-9,22,-5,minecraft:stone)
B(-9,22,-4,minecraft:rail[shape=east_west])
B(-9,22,-3,minecraft:cobblestone_slab)
B(-9,22,-2,minecraft:rail[shape=south_east])
B(-9,22,-1,minecraft:rail)
B(-9,22,0,minecraft:rail[shape=north_east])
B(-9,22,1,minecraft:cobblestone_slab)
B(-9,22,2,minecraft:rail[shape=east_west])
B(-9,22,3,minecraft:oak_fence)
B(-9,22,4,minecraft:stone)
B(-9,22,5,minecraft:stone)
B(-9,22,6,minecraft:stone)
B(-9,22,7,minecraft:stone)
B(-9,22,8,minecraft:stone)
B(-9,22,9,minecraft:stone)
B(-9,22,10,minecraft:grass_block)
B(-9,22,11,minecraft:grass_block)
B(-9,22,12,minecraft:grass_block)
B(-9,23,-10,minecraft:grass_block)
B(-9,23,-9,minecraft:stone)
B(-9,23,-8,minecraft:stone)
B(-9,23,-7,minecraft:stone)
B(-9,23,-6,minecraft:stone)
B(-9,23,-5,minecraft:oak_fence)
B(-9,23,-4,minecraft:air)
B(-9,23,-3,minecraft:air)
B(-9,23,-2,minecraft:air)
B(-9,23,-1,minecraft:air)
B(-9,23,0,minecraft:air)
B(-9,23,1,minecraft:air)
B(-9,23,2,minecraft:air)
B(-9,23,3,minecraft:stone)
B(-9,23,4,minecraft:stone)
B(-9,23,5,minecraft:stone)
B(-9,23,6,minecraft:stone)
B(-9,23,7,minecraft:stone)
B(-9,23,8,minecraft:stone)
B(-9,23,9,minecraft:stone)
B(-9,24,-9,minecraft:stone)
B(-9,24,-8,minecraft:stone)
B(-9,24,-7,minecraft:stone)
B(-9,24,-6,minecraft:stone)
B(-9,24,-5,minecraft:oak_fence)
B(-9,24,-4,minecraft:air)
B(-9,24,-3,minecraft:air)
B(-9,24,-2,minecraft:air)
B(-9,24,-1,minecraft:air)
B(-9,24,0,minecraft:air)
B(-9,24,1,minecraft:air)
B(-9,24,2,minecraft:air)
B(-9,24,3,minecraft:stone)
B(-9,24,4,minecraft:stone)
B(-9,24,5,minecraft:stone)
B(-9,24,6,minecraft:stone)
B(-9,24,7,minecraft:stone)
B(-9,24,8,minecraft:stone)
B(-9,24,9,minecraft:stone)
B(-9,25,-9,minecraft:stone)
B(-9,25,-8,minecraft:stone)
B(-9,25,-7,minecraft:stone)
B(-9,25,-6,minecraft:stone)
B(-9,25,-5,minecraft:stone)
B(-9,25,-4,minecraft:stone)
B(-9,25,-3,minecraft:stone)
B(-9,25,-2,minecraft:stone)
B(-9,25,-1,minecraft:spruce_log[axis=x])
B(-9,25,0,minecraft:stone)
B(-9,25,1,minecraft:stone)
B(-9,25,2,minecraft:stone)
B(-9,25,3,minecraft:stone)
B(-9,25,4,minecraft:stone)
B(-9,25,5,minecraft:stone)
B(-9,25,6,minecraft:stone)
B(-9,25,7,minecraft:stone)
B(-9,25,8,minecraft:stone)
B(-9,25,9,minecraft:stone)
B(-9,26,-9,minecraft:grass_block)
B(-9,26,-8,minecraft:stone)
B(-9,26,-7,minecraft:stone)
B(-9,26,-6,minecraft:stone)
B(-9,26,-5,minecraft:stone)
B(-9,26,-4,minecraft:stone)
B(-9,26,-3,minecraft:stone)
B(-9,26,-2,minecraft:stone)
B(-9,26,-1,minecraft:stone)
B(-9,26,0,minecraft:stone)
B(-9,26,1,minecraft:stone)
B(-9,26,2,minecraft:stone)
B(-9,26,3,minecraft:stone)
B(-9,26,4,minecraft:stone)
B(-9,26,5,minecraft:stone)
B(-9,26,6,minecraft:stone)
B(-9,26,7,minecraft:stone)
B(-9,26,8,minecraft:stone)
B(-9,26,9,minecraft:grass_block)
B(-9,27,-8,minecraft:stone)
B(-9,27,-7,minecraft:stone)
B(-9,27,-6,minecraft:stone)
B(-9,27,-5,minecraft:stone)
B(-9,27,-4,minecraft:stone)
B(-9,27,-3,minecraft:stone)
B(-9,27,-2,minecraft:stone)
B(-9,27,-1,minecraft:stone)
B(-9,27,0,minecraft:stone)
B(-9,27,1,minecraft:stone)
B(-9,27,2,minecraft:stone)
B(-9,27,3,minecraft:stone)
B(-9,27,4,minecraft:stone)
B(-9,27,5,minecraft:stone)
B(-9,27,6,minecraft:stone)
B(-9,27,7,minecraft:stone)
B(-9,27,8,minecraft:stone)
B(-9,28,-8,minecraft:grass_block)
B(-9,28,-7,minecraft:stone)
B(-9,28,-6,minecraft:stone)
B(-9,28,-5,minecraft:stone)
B(-9,28,-4,minecraft:stone)
B(-9,28,-3,minecraft:stone)
B(-9,28,-2,minecraft:stone)
B(-9,28,-1,minecraft:stone)
B(-9,28,0,minecraft:stone)
B(-9,28,1,minecraft:stone)
B(-9,28,2,minecraft:stone)
B(-9,28,3,minecraft:stone)
B(-9,28,4,minecraft:stone)
B(-9,28,5,minecraft:stone)
B(-9,28,6,minecraft:stone)
B(-9,28,7,minecraft:stone)
B(-9,28,8,minecraft:stone)
B(-9,29,-7,minecraft:stone)
B(-9,29,-6,minecraft:stone)
B(-9,29,-5,minecraft:stone)
B(-9,29,-4,minecraft:stone)
B(-9,29,-3,minecraft:stone)
B(-9,29,-2,minecraft:stone)
B(-9,29,-1,minecraft:stone)
B(-9,29,0,minecraft:stone)
B(-9,29,1,minecraft:stone)
B(-9,29,2,minecraft:stone)
B(-9,29,3,minecraft:stone)
B(-9,29,4,minecraft:stone)
B(-9,29,5,minecraft:stone)
B(-9,29,6,minecraft:stone)
B(-9,29,7,minecraft:stone)
B(-9,29,8,minecraft:stone)
B(-9,30,-7,minecraft:grass_block)
B(-9,30,-6,minecraft:stone)
B(-9,30,-5,minecraft:stone)
B(-9,30,-4,minecraft:stone)
B(-9,30,-3,minecraft:stone)
B(-9,30,-2,minecraft:stone)
B(-9,30,-1,minecraft:stone)
B(-9,30,0,minecraft:stone)
B(-9,30,1,minecraft:stone)
B(-9,30,2,minecraft:stone)
B(-9,30,3,minecraft:stone)
B(-9,30,4,minecraft:stone)
B(-9,30,5,minecraft:stone)
B(-9,30,6,minecraft:stone)
B(-9,30,7,minecraft:stone)
B(-9,30,8,minecraft:grass_block)
B(-9,31,-6,minecraft:grass_block)
B(-9,31,-5,minecraft:grass_block)
B(-9,31,-4,minecraft:stone)
B(-9,31,-3,minecraft:stone)
B(-9,31,-2,minecraft:stone)
B(-9,31,-1,minecraft:stone)
B(-9,31,0,minecraft:grass_block)
B(-9,31,1,minecraft:grass_block)
B(-9,31,2,minecraft:grass_block)
B(-9,31,3,minecraft:grass_block)
B(-9,31,4,minecraft:stone)
B(-9,31,5,minecraft:grass_block)
B(-9,31,6,minecraft:grass_block)
B(-9,31,7,minecraft:grass_block)
B(-9,32,-2,minecraft:grass_block)
B(-9,32,4,minecraft:grass_block)
B(-8,20,-4,minecraft:stone)
B(-8,20,-3,minecraft:stone)
B(-8,20,-2,minecraft:stone)
B(-8,21,-5,minecraft:spruce_log[axis=x])
B(-8,21,-4,minecraft:stone)
B(-8,21,-3,minecraft:stone)
B(-8,21,-2,minecraft:stone)
B(-8,21,-1,minecraft:spruce_log[axis=x])
B(-8,21,0,minecraft:stone)
B(-8,21,1,minecraft:stone)
B(-8,21,2,minecraft:stone)
B(-8,21,3,minecraft:spruce_log)
B(-8,22,-11,minecraft:grass_block)
B(-8,22,-10,minecraft:stone)
B(-8,22,-9,minecraft:stone)
B(-8,22,-8,minecraft:stone)
B(-8,22,-7,minecraft:stone)
B(-8,22,-6,minecraft:stone)
B(-8,22,-5,minecraft:spruce_log)
B(-8,22,-4,minecraft:rail[shape=east_west])
B(-8,22,-3,minecraft:cobblestone_slab)
B(-8,22,-2,minecraft:rail[shape=east_west])
B(-8,22,-1,minecraft:spruce_log)
B(-8,22,0,minecraft:rail[shape=ascending_east])
B(-8,22,1,minecraft:cobblestone_stairs[facing=east,half=bottom,shape=straight,waterlogged=false])
B(-8,22,2,minecraft:rail[shape=ascending_east])
B(-8,22,3,minecraft:spruce_log)
B(-8,22,4,minecraft:stone)
B(-8,22,5,minecraft:stone)
B(-8,22,6,minecraft:stone)
B(-8,22,7,minecraft:stone)
B(-8,22,8,minecraft:stone)
B(-8,22,9,minecraft:stone)
B(-8,22,10,minecraft:stone)
B(-8,22,11,minecraft:grass_block)
B(-8,22,12,minecraft:grass_block)
B(-8,23,-10,minecraft:stone)
B(-8,23,-9,minecraft:stone)
B(-8,23,-8,minecraft:stone)
B(-8,23,-7,minecraft:stone)
B(-8,23,-6,minecraft:stone)
B(-8,23,-5,minecraft:spruce_log)
B(-8,23,-4,minecraft:air)
B(-8,23,-3,minecraft:air)
B(-8,23,-2,minecraft:air)
B(-8,23,-1,minecraft:spruce_log)
B(-8,23,0,minecraft:air)
B(-8,23,1,minecraft:air)
B(-8,23,2,minecraft:air)
B(-8,23,3,minecraft:spruce_log)
B(-8,23,4,minecraft:stone)
B(-8,23,5,minecraft:stone)
B(-8,23,6,minecraft:stone)
B(-8,23,7,minecraft:stone)
B(-8,23,8,minecraft:stone)
B(-8,23,9,minecraft:stone)
B(-8,23,10,minecraft:stone)
B(-8,24,-10,minecraft:stone)
B(-8,24,-9,minecraft:stone)
B(-8,24,-8,minecraft:stone)
B(-8,24,-7,minecraft:stone)
B(-8,24,-6,minecraft:stone)
B(-8,24,-5,minecraft:spruce_log)
B(-8,24,-4,minecraft:air)
B(-8,24,-3,minecraft:air)
B(-8,24,-2,minecraft:air)
B(-8,24,-1,minecraft:spruce_log)
B(-8,24,0,minecraft:air)
B(-8,24,1,minecraft:air)
B(-8,24,2,minecraft:air)
B(-8,24,3,minecraft:spruce_log)
B(-8,24,4,minecraft:stone)
B(-8,24,5,minecraft:stone)
B(-8,24,6,minecraft:stone)
B(-8,24,7,minecraft:stone)
B(-8,24,8,minecraft:stone)
B(-8,24,9,minecraft:stone)
B(-8,24,10,minecraft:stone)
B(-8,25,-10,minecraft:grass_block)
B(-8,25,-9,minecraft:stone)
B(-8,25,-8,minecraft:stone)
B(-8,25,-7,minecraft:stone)
B(-8,25,-6,minecraft:stone)
B(-8,25,-5,minecraft:stone)
B(-8,25,-4,minecraft:spruce_log[axis=z])
B(-8,25,-3,minecraft:spruce_log[axis=z])
B(-8,25,-2,minecraft:spruce_log[axis=z])
B(-8,25,-1,minecraft:spruce_log[axis=x])
B(-8,25,0,minecraft:air)
B(-8,25,1,minecraft:air)
B(-8,25,2,minecraft:air)
B(-8,25,3,minecraft:spruce_log[axis=x])
B(-8,25,4,minecraft:stone)
B(-8,25,5,minecraft:stone)
B(-8,25,6,minecraft:stone)
B(-8,25,7,minecraft:stone)
B(-8,25,8,minecraft:stone)
B(-8,25,9,minecraft:stone)
B(-8,25,10,minecraft:grass_block)
B(-8,26,-9,minecraft:stone)
B(-8,26,-8,minecraft:stone)
B(-8,26,-7,minecraft:stone)
B(-8,26,-6,minecraft:stone)
B(-8,26,-5,minecraft:stone)
B(-8,26,-4,minecraft:stone)
B(-8,26,-3,minecraft:stone)
B(-8,26,-2,minecraft:stone)
B(-8,26,-1,minecraft:stone)
B(-8,26,0,minecraft:spruce_log[axis=z])
B(-8,26,1,minecraft:spruce_log[axis=z])
B(-8,26,2,minecraft:spruce_log[axis=z])
B(-8,26,3,minecraft:stone)
B(-8,26,4,minecraft:stone)
B(-8,26,5,minecraft:stone)
B(-8,26,6,minecraft:stone)
B(-8,26,7,minecraft:stone)
B(-8,26,8,minecraft:stone)
B(-8,26,9,minecraft:stone)
B(-8,27,-9,minecraft:grass_block)
B(-8,27,-8,minecraft:stone)
B(-8,27,-7,minecraft:stone)
B(-8,27,-6,minecraft:stone)
B(-8,27,-5,minecraft:stone)
B(-8,27,-4,minecraft:stone)
B(-8,27,-3,minecraft:stone)
B(-8,27,-2,minecraft:stone)
B(-8,27,-1,minecraft:stone)
B(-8,27,0,minecraft:stone)
B(-8,27,1,minecraft:stone)
B(-8,27,2,minecraft:stone)
B(-8,27,3,minecraft:stone)
B(-8,27,4,minecraft:stone)
B(-8,27,5,minecraft:stone)
B(-8,27,6,minecraft:stone)
B(-8,27,7,minecraft:stone)
B(-8,27,8,minecraft:stone)
B(-8,27,9,minecraft:stone)
B(-8,28,-8,minecraft:stone)
B(-8,28,-7,minecraft:stone)
B(-8,28,-6,minecraft:stone)
B(-8,28,-5,minecraft:stone)
B(-8,28,-4,minecraft:stone)
B(-8,28,-3,minecraft:stone)
B(-8,28,-2,minecraft:stone)
B(-8,28,-1,minecraft:stone)
B(-8,28,0,minecraft:stone)
B(-8,28,1,minecraft:stone)
B(-8,28,2,minecraft:stone)
B(-8,28,3,minecraft:stone)
B(-8,28,4,minecraft:stone)
B(-8,28,5,minecraft:stone)
B(-8,28,6,minecraft:stone)
B(-8,28,7,minecraft:stone)
B(-8,28,8,minecraft:stone)
B(-8,28,9,minecraft:stone)
B(-8,29,-8,minecraft:grass_block)
B(-8,29,-7,minecraft:stone)
B(-8,29,-6,minecraft:stone)
B(-8,29,-5,minecraft:stone)
B(-8,29,-4,minecraft:stone)
B(-8,29,-3,minecraft:stone)
B(-8,29,-2,minecraft:stone)
B(-8,29,-1,minecraft:stone)
B(-8,29,0,minecraft:stone)
B(-8,29,1,minecraft:stone)
B(-8,29,2,minecraft:stone)
B(-8,29,3,minecraft:stone)
B(-8,29,4,minecraft:stone)
B(-8,29,5,minecraft:stone)
B(-8,29,6,minecraft:stone)
B(-8,29,7,minecraft:stone)
B(-8,29,8,minecraft:stone)
B(-8,29,9,minecraft:grass_block)
B(-8,30,-7,minecraft:grass_block)
B(-8,30,-6,minecraft:grass_block)
B(-8,30,-5,minecraft:stone)
B(-8,30,-4,minecraft:stone)
B(-8,30,-3,minecraft:stone)
B(-8,30,-2,minecraft:stone)
B(-8,30,-1,minecraft:stone)
B(-8,30,0,minecraft:stone)
B(-8,30,1,minecraft:stone)
B(-8,30,2,minecraft:stone)
B(-8,30,3,minecraft:stone)
B(-8,30,4,minecraft:stone)
B(-8,30,5,minecraft:stone)
B(-8,30,6,minecraft:stone)
B(-8,30,7,minecraft:stone)
B(-8,30,8,minecraft:grass_block)
B(-8,31,-5,minecraft:stone)
B(-8,31,-4,minecraft:stone)
B(-8,31,-3,minecraft:stone)
B(-8,31,-2,minecraft:stone)
B(-8,31,-1,minecraft:stone)
B(-8,31,0,minecraft:stone)
B(-8,31,1,minecraft:stone)
B(-8,31,2,minecraft:grass_block)
B(-8,31,3,minecraft:grass_block)
B(-8,31,4,minecraft:stone)
B(-8,31,5,minecraft:stone)
B(-8,31,6,minecraft:stone)
B(-8,31,7,minecraft:grass_block)
B(-8,32,-3,minecraft:grass_block)
B(-8,32,-2,minecraft:grass_block)
B(-8,32,-1,minecraft:grass_block)
B(-8,32,0,minecraft:grass_block)
B(-8,32,1,minecraft:grass_block)
B(-8,32,4,minecraft:grass_block)
B(-8,32,5,minecraft:grass_block)
B(-8,32,6,minecraft:grass_block)
B(-7,19,-4,minecraft:stone)
B(-7,19,-3,minecraft:stone)
B(-7,19,-2,minecraft:stone)
B(-7,20,-4,minecraft:stone)
B(-7,20,-3,minecraft:stone)
B(-7,20,-2,minecraft:stone)
B(-7,21,-5,minecraft:spruce_log[axis=x])
B(-7,21,-4,minecraft:rail[shape=ascending_west])
B(-7,21,-3,minecraft:cobblestone_stairs[facing=west,half=bottom,shape=straight,waterlogged=false])
B(-7,21,-2,minecraft:rail[shape=ascending_west])
B(-7,21,-1,minecraft:spruce_log[axis=x])
B(-7,21,1,minecraft:stone)
B(-7,21,2,minecraft:stone)
B(-7,22,-11,minecraft:grass_block)
B(-7,22,-10,minecraft:stone)
B(-7,22,-9,minecraft:stone)
B(-7,22,-8,minecraft:stone)
B(-7,22,-7,minecraft:stone)
B(-7,22,-6,minecraft:stone)
B(-7,22,-5,minecraft:stone)
B(-7,22,-4,minecraft:air)
B(-7,22,-3,minecraft:air)
B(-7,22,-2,minecraft:air)
B(-7,22,-1,minecraft:oak_fence)
B(-7,22,0,minecraft:stone)
B(-7,22,1,minecraft:stone)
B(-7,22,2,minecraft:stone)
B(-7,22,3,minecraft:stone)
B(-7,22,4,minecraft:stone)
B(-7,22,5,minecraft:stone)
B(-7,22,6,minecraft:stone)
B(-7,22,7,minecraft:stone)
B(-7,22,8,minecraft:stone)
B(-7,22,9,minecraft:stone)
B(-7,22,10,minecraft:stone)
B(-7,22,11,minecraft:grass_block)
B(-7,22,12,minecraft:grass_block)
B(-7,23,-10,minecraft:stone)
B(-7,23,-9,minecraft:stone)
B(-7,23,-8,minecraft:stone)
B(-7,23,-7,minecraft:stone)
B(-7,23,-6,minecraft:stone)
B(-7,23,-5,minecraft:stone)
B(-7,23,-4,minecraft:air)
B(-7,23,-3,minecraft:air)
B(-7,23,-2,minecraft:air)
B(-7,23,-1,minecraft:oak_fence)
B(-7,23,0,minecraft:rail[shape=ascending_east])
B(-7,23,1,minecraft:cobblestone_stairs[facing=east,half=bottom,shape=straight,waterlogged=false])
B(-7,23,2,minecraft:rail[shape=ascending_east])
B(-7,23,3,minecraft:stone)
B(-7,23,4,minecraft:stone)
B(-7,23,5,minecraft:stone)
B(-7,23,6,minecraft:stone)
B(-7,23,7,minecraft:stone)
B(-7,23,8,minecraft:stone)
B(-7,23,9,minecraft:stone)
B(-7,23,10,minecraft:stone)
B(-7,24,-10,minecraft:grass_block)
B(-7,24,-9,minecraft:stone)
B(-7,24,-8,minecraft:stone)
B(-7,24,-7,minecraft:stone)
B(-7,24,-6,minecraft:stone)
B(-7,24,-5,minecraft:stone)
B(-7,24,-4,minecraft:air)
B(-7,24,-3,minecraft:air)
B(-7,24,-2,minecraft:air)
B(-7,24,-1,minecraft:oak_fence)
B(-7,24,0,minecraft:air)
B(-7,24,1,minecraft:air)
B(-7,24,2,minecraft:air)
B(-7,24,3,minecraft:stone)
B(-7,24,4,minecraft:stone)
B(-7,24,5,minecraft:stone)
B(-7,24,6,minecraft:stone)
B(-7,24,7,minecraft:stone)
B(-7,24,8,minecraft:stone)
B(-7,24,9,minecraft:stone)
B(-7,24,10,minecraft:stone)
B(-7,25,-9,minecraft:stone)
B(-7,25,-8,minecraft:stone)
B(-7,25,-7,minecraft:stone)
B(-7,25,-6,minecraft:stone)
B(-7,25,-5,minecraft:stone)
B(-7,25,-4,minecraft:stone)
B(-7,25,-3,minecraft:stone)
B(-7,25,-2,minecraft:stone)
B(-7,25,-1,minecraft:spruce_log[axis=x])
B(-7,25,0,minecraft:air)
B(-7,25,1,minecraft:air)
B(-7,25,2,minecraft:air)
B(-7,25,3,minecraft:spruce_log[axis=x])
B(-7,25,4,minecraft:stone)
B(-7,25,5,minecraft:stone)
B(-7,25,6,minecraft:stone)
B(-7,25,7,minecraft:stone)
B(-7,25,8,minecraft:stone)
B(-7,25,9,minecraft:stone)
B(-7,25,10,minecraft:stone)
B(-7,26,-9,minecraft:stone)
B(-7,26,-8,minecraft:stone)
B(-7,26,-7,minecraft:stone)
B(-7,26,-6,minecraft:stone)
B(-7,26,-5,minecraft:stone)
B(-7,26,-4,minecraft:stone)
B(-7,26,-3,minecraft:stone)
B(-7,26,-2,minecraft:stone)
B(-7,26,-1,minecraft:stone)
B(-7,26,0,minecraft:air)
B(-7,26,1,minecraft:wall_torch[facing=east])
B(-7,26,2,minecraft:air)
B(-7,26,3,minecraft:stone)
B(-7,26,4,minecraft:stone)
B(-7,26,5,minecraft:stone)
B(-7,26,6,minecraft:stone)
B(-7,26,7,minecraft:stone)
B(-7,26,8,minecraft:stone)
B(-7,26,9,minecraft:stone)
B(-7,26,10,minecraft:stone)
B(-7,27,-9,minecraft:grass_block)
B(-7,27,-8,minecraft:stone)
B(-7,27,-7,minecraft:stone)
B(-7,27,-6,minecraft:stone)
B(-7,27,-5,minecraft:stone)
B(-7,27,-4,minecraft:stone)
B(-7,27,-3,minecraft:stone)
B(-7,27,-2,minecraft:stone)
B(-7,27,-1,minecraft:stone)
B(-7,27,0,minecraft:stone)
B(-7,27,1,minecraft:stone)
B(-7,27,2,minecraft:stone)
B(-7,27,3,minecraft:stone)
B(-7,27,4,minecraft:stone)
B(-7,27,5,minecraft:stone)
B(-7,27,6,minecraft:stone)
B(-7,27,7,minecraft:stone)
B(-7,27,8,minecraft:stone)
B(-7,27,9,minecraft:stone)
B(-7,27,10,minecraft:grass_block)
B(-7,28,-8,minecraft:stone)
B(-7,28,-7,minecraft:stone)
B(-7,28,-6,minecraft:stone)
B(-7,28,-5,minecraft:stone)
B(-7,28,-4,minecraft:stone)
B(-7,28,-3,minecraft:stone)
B(-7,28,-2,minecraft:stone)
B(-7,28,-1,minecraft:stone)
B(-7,28,0,minecraft:stone)
B(-7,28,1,minecraft:stone)
B(-7,28,2,minecraft:stone)
B(-7,28,3,minecraft:stone)
B(-7,28,4,minecraft:stone)
B(-7,28,5,minecraft:stone)
B(-7,28,6,minecraft:stone)
B(-7,28,7,minecraft:stone)
B(-7,28,8,minecraft:stone)
B(-7,28,9,minecraft:stone)
B(-7,29,-8,minecraft:stone)
B(-7,29,-7,minecraft:stone)
B(-7,29,-6,minecraft:stone)
B(-7,29,-5,minecraft:stone)
B(-7,29,-4,minecraft:stone)
B(-7,29,-3,minecraft:stone)
B(-7,29,-2,minecraft:stone)
B(-7,29,-1,minecraft:stone)
B(-7,29,0,minecraft:stone)
B(-7,29,1,minecraft:stone)
B(-7,29,2,minecraft:stone)
B(-7,29,3,minecraft:stone)
B(-7,29,4,minecraft:stone)
B(-7,29,5,minecraft:stone)
B(-7,29,6,minecraft:stone)
B(-7,29,7,minecraft:stone)
B(-7,29,8,minecraft:stone)
B(-7,29,9,minecraft:stone)
B(-7,30,-8,minecraft:grass_block)
B(-7,30,-7,minecraft:grass_block)
B(-7,30,-6,minecraft:stone)
B(-7,30,-5,minecraft:stone)
B(-7,30,-4,minecraft:stone)
B(-7,30,-3,minecraft:stone)
B(-7,30,-2,minecraft:stone)
B(-7,30,-1,minecraft:stone)
B(-7,30,0,minecraft:stone)
B(-7,30,1,minecraft:stone)
B(-7,30,2,minecraft:stone)
B(-7,30,3,minecraft:stone)
B(-7,30,4,minecraft:stone)
B(-7,30,5,minecraft:stone)
B(-7,30,6,minecraft:stone)
B(-7,30,7,minecraft:stone)
B(-7,30,8,minecraft:stone)
B(-7,30,9,minecraft:grass_block)
B(-7,31,-6,minecraft:grass_block)
B(-7,31,-5,minecraft:stone)
B(-7,31,-4,minecraft:stone)
B(-7,31,-3,minecraft:stone)
B(-7,31,-2,minecraft:stone)
B(-7,31,-1,minecraft:stone)
B(-7,31,0,minecraft:stone)
B(-7,31,1,minecraft:stone)
B(-7,31,2,minecraft:stone)
B(-7,31,3,minecraft:stone)
B(-7,31,4,minecraft:stone)
B(-7,31,5,minecraft:stone)
B(-7,31,6,minecraft:stone)
B(-7,31,7,minecraft:grass_block)
B(-7,31,8,minecraft:grass_block)
B(-7,32,-4,minecraft:grass_block)
B(-7,32,-3,minecraft:grass_block)
B(-7,32,-2,minecraft:grass_block)
B(-7,32,-1,minecraft:grass_block)
B(-7,32,0,minecraft:stone)
B(-7,32,1,minecraft:stone)
B(-7,32,2,minecraft:grass_block)
B(-7,32,3,minecraft:grass_block)
B(-7,32,4,minecraft:grass_block)
B(-7,32,5,minecraft:grass_block)
B(-7,32,6,minecraft:grass_block)
B(-7,33,0,minecraft:grass_block)
B(-7,33,1,minecraft:grass_block)
B(-6,4,1,minecraft:air)
B(-6,16,-5,minecraft:spruce_log[axis=x])
B(-6,16,-1,minecraft:spruce_log[axis=x])
B(-6,18,-4,minecraft:stone)
B(-6,18,-3,minecraft:stone)
B(-6,18,-2,minecraft:stone)
B(-6,19,-4,minecraft:stone)
B(-6,19,-3,minecraft:stone)
B(-6,19,-2,minecraft:stone)
B(-6,20,-4,minecraft:rail[shape=ascending_west])
B(-6,20,-3,minecraft:cobblestone_stairs[facing=west,half=bottom,shape=straight,waterlogged=false])
B(-6,20,-2,minecraft:rail[shape=ascending_west])
B(-6,21,-5,minecraft:spruce_log[axis=x])
B(-6,21,-4,minecraft:air)
B(-6,21,-3,minecraft:air)
B(-6,21,-2,minecraft:air)
B(-6,21,-1,minecraft:spruce_log[axis=x])
B(-6,21,1,minecraft:stone)
B(-6,22,-11,minecraft:grass_block)
B(-6,22,-10,minecraft:grass_block)
B(-6,22,-9,minecraft:stone)
B(-6,22,-8,minecraft:stone)
B(-6,22,-7,minecraft:stone)
B(-6,22,-6,minecraft:stone)
B(-6,22,-5,minecraft:stone)
B(-6,22,-4,minecraft:air)
B(-6,22,-3,minecraft:air)
B(-6,22,-2,minecraft:air)
B(-6,22,-1,minecraft:oak_fence)
B(-6,22,0,minecraft:stone)
B(-6,22,1,minecraft:stone)
B(-6,22,2,minecraft:stone)
B(-6,22,3,minecraft:stone)
B(-6,22,4,minecraft:stone)
B(-6,22,5,minecraft:stone)
B(-6,22,6,minecraft:stone)
B(-6,22,7,minecraft:stone)
B(-6,22,8,minecraft:stone)
B(-6,22,9,minecraft:stone)
B(-6,22,10,minecraft:grass_block)
B(-6,22,11,minecraft:grass_block)
B(-6,22,12,minecraft:grass_block)
B(-6,23,-9,minecraft:stone)
B(-6,23,-8,minecraft:stone)
B(-6,23,-7,minecraft:stone)
B(-6,23,-6,minecraft:stone)
B(-6,23,-5,minecraft:stone)
B(-6,23,-4,minecraft:air)
B(-6,23,-3,minecraft:air)
B(-6,23,-2,minecraft:air)
B(-6,23,-1,minecraft:oak_fence)
B(-6,23,0,minecraft:stone)
B(-6,23,1,minecraft:stone)
B(-6,23,2,minecraft:stone)
B(-6,23,3,minecraft:stone)
B(-6,23,4,minecraft:stone)
B(-6,23,5,minecraft:stone)
B(-6,23,6,minecraft:stone)
B(-6,23,7,minecraft:stone)
B(-6,23,8,minecraft:stone)
B(-6,23,9,minecraft:stone)
B(-6,24,-9,minecraft:stone)
B(-6,24,-8,minecraft:stone)
B(-6,24,-7,minecraft:stone)
B(-6,24,-6,minecraft:stone)
B(-6,24,-5,minecraft:stone)
B(-6,24,-4,minecraft:stone)
B(-6,24,-3,minecraft:stone)
B(-6,24,-2,minecraft:stone)
B(-6,24,-1,minecraft:stone)
B(-6,24,0,minecraft:rail[shape=ascending_east])
B(-6,24,1,minecraft:cobblestone_stairs[facing=east,half=bottom,shape=straight,waterlogged=false])
B(-6,24,2,minecraft:rail[shape=ascending_east])
B(-6,24,3,minecraft:stone)
B(-6,24,4,minecraft:stone)
B(-6,24,5,minecraft:stone)
B(-6,24,6,minecraft:stone)
B(-6,24,7,minecraft:stone)
B(-6,24,8,minecraft:stone)
B(-6,24,9,minecraft:stone)
B(-6,25,-9,minecraft:stone)
B(-6,25,-8,minecraft:stone)
B(-6,25,-7,minecraft:stone)
B(-6,25,-6,minecraft:stone)
B(-6,25,-5,minecraft:stone)
B(-6,25,-4,minecraft:stone)
B(-6,25,-3,minecraft:stone)
B(-6,25,-2,minecraft:stone)
B(-6,25,-1,minecraft:spruce_log[axis=x])
B(-6,25,0,minecraft:air)
B(-6,25,1,minecraft:air)
B(-6,25,2,minecraft:air)
B(-6,25,3,minecraft:spruce_log[axis=x])
B(-6,25,4,minecraft:stone)
B(-6,25,5,minecraft:stone)
B(-6,25,6,minecraft:stone)
B(-6,25,7,minecraft:stone)
B(-6,25,8,minecraft:stone)
B(-6,25,9,minecraft:stone)
B(-6,26,-9,minecraft:grass_block)
B(-6,26,-8,minecraft:stone)
B(-6,26,-7,minecraft:stone)
B(-6,26,-6,minecraft:stone)
B(-6,26,-5,minecraft:stone)
B(-6,26,-4,minecraft:stone)
B(-6,26,-3,minecraft:stone)
B(-6,26,-2,minecraft:stone)
B(-6,26,-1,minecraft:stone)
B(-6,26,0,minecraft:air)
B(-6,26,1,minecraft:air)
B(-6,26,2,minecraft:air)
B(-6,26,3,minecraft:oak_fence)
B(-6,26,4,minecraft:stone)
B(-6,26,5,minecraft:stone)
B(-6,26,6,minecraft:stone)
B(-6,26,7,minecraft:stone)
B(-6,26,8,minecraft:stone)
B(-6,26,9,minecraft:stone)
B(-6,27,-8,minecraft:grass_block)
B(-6,27,-7,minecraft:stone)
B(-6,27,-6,minecraft:stone)
B(-6,27,-5,minecraft:stone)
B(-6,27,-4,minecraft:stone)
B(-6,27,-3,minecraft:stone)
B(-6,27,-2,minecraft:stone)
B(-6,27,-1,minecraft:stone)
B(-6,27,0,minecraft:air)
B(-6,27,1,minecraft:air)
B(-6,27,2,minecraft:air)
B(-6,27,3,minecraft:oak_fence)
B(-6,27,4,minecraft:stone)
B(-6,27,5,minecraft:stone)
B(-6,27,6,minecraft:stone)
B(-6,27,7,minecraft:stone)
B(-6,27,8,minecraft:stone)
B(-6,27,9,minecraft:grass_block)
B(-6,28,-7,minecraft:grass_block)
B(-6,28,-6,minecraft:stone)
B(-6,28,-5,minecraft:stone)
B(-6,28,-4,minecraft:stone)
B(-6,28,-3,minecraft:stone)
B(-6,28,-2,minecraft:stone)
B(-6,28,-1,minecraft:stone)
B(-6,28,0,minecraft:stone)
B(-6,28,1,minecraft:stone)
B(-6,28,2,minecraft:stone)
B(-6,28,3,minecraft:stone)
B(-6,28,4,minecraft:stone)
B(-6,28,5,minecraft:stone)
B(-6,28,6,minecraft:stone)
B(-6,28,7,minecraft:stone)
B(-6,28,8,minecraft:stone)
B(-6,29,-6,minecraft:stone)
B(-6,29,-5,minecraft:stone)
B(-6,29,-4,minecraft:stone)
B(-6,29,-3,minecraft:stone)
B(-6,29,-2,minecraft:stone)
B(-6,29,-1,minecraft:stone)
B(-6,29,0,minecraft:stone)
B(-6,29,1,minecraft:stone)
B(-6,29,2,minecraft:stone)
B(-6,29,3,minecraft:stone)
B(-6,29,4,minecraft:stone)
B(-6,29,5,minecraft:stone)
B(-6,29,6,minecraft:stone)
B(-6,29,7,minecraft:stone)
B(-6,29,8,minecraft:grass_block)
B(-6,30,-6,minecraft:grass_block)
B(-6,30,-5,minecraft:stone)
B(-6,30,-4,minecraft:stone)
B(-6,30,-3,minecraft:stone)
B(-6,30,-2,minecraft:stone)
B(-6,30,-1,minecraft:stone)
B(-6,30,0,minecraft:stone)
B(-6,30,1,minecraft:stone)
B(-6,30,2,minecraft:stone)
B(-6,30,3,minecraft:stone)
B(-6,30,4,minecraft:stone)
B(-6,30,5,minecraft:stone)
B(-6,30,6,minecraft:stone)
B(-6,30,7,minecraft:stone)
B(-6,31,-5,minecraft:grass_block)
B(-6,31,-4,minecraft:stone)
B(-6,31,-3,minecraft:stone)
B(-6,31,-2,minecraft:stone)
B(-6,31,-1,minecraft:stone)
B(-6,31,0,minecraft:stone)
B(-6,31,1,minecraft:stone)
B(-6,31,2,minecraft:stone)
B(-6,31,3,minecraft:stone)
B(-6,31,4,minecraft:stone)
B(-6,31,5,minecraft:stone)
B(-6,31,6,minecraft:stone)
B(-6,31,7,minecraft:stone)
B(-6,32,-4,minecraft:grass_block)
B(-6,32,-3,minecraft:grass_block)
B(-6,32,-2,minecraft:grass_block)
B(-6,32,-1,minecraft:dirt)
B(-6,32,0,minecraft:stone)
B(-6,32,1,minecraft:stone)
B(-6,32,2,minecraft:stone)
B(-6,32,3,minecraft:stone)
B(-6,32,4,minecraft:grass_block)
B(-6,32,5,minecraft:grass_block)
B(-6,32,6,minecraft:grass_block)
B(-6,32,7,minecraft:grass_block)
B(-6,33,-1,minecraft:grass_block)
B(-6,33,0,minecraft:grass_block)
B(-6,33,1,minecraft:grass_block)
B(-6,33,2,minecraft:grass_block)
B(-6,33,3,minecraft:grass_block)
B(-5,0,-1,minecraft:spruce_log)
B(-5,1,-1,minecraft:spruce_log)
B(-5,2,-1,minecraft:spruce_log)
B(-5,3,-2,minecraft:oak_fence)
B(-5,3,-1,minecraft:spruce_log)
B(-5,3,1,minecraft:air)
B(-5,3,2,minecraft:air)
B(-5,4,-2,minecraft:oak_fence)
B(-5,4,-1,minecraft:spruce_log)
B(-5,4,1,minecraft:air)
B(-5,4,2,minecraft:air)
B(-5,4,3,minecraft:air)
B(-5,5,-2,minecraft:oak_fence)
B(-5,5,-1,minecraft:spruce_log[axis=x])
B(-5,5,1,minecraft:air)
B(-5,5,2,minecraft:air)
B(-5,5,3,minecraft:air)
B(-5,16,-5,minecraft:spruce_log[axis=x])
B(-5,16,-1,minecraft:spruce_log[axis=x])
B(-5,17,-4,minecraft:stone)
B(-5,17,-2,minecraft:stone)
B(-5,18,-4,minecraft:stone)
B(-5,18,-3,minecraft:stone)
B(-5,18,-2,minecraft:stone)
B(-5,19,-4,minecraft:rail[shape=ascending_west])
B(-5,19,-3,minecraft:cobblestone_stairs[facing=west,half=bottom,shape=straight,waterlogged=false])
B(-5,19,-2,minecraft:rail[shape=ascending_west])
B(-5,20,-4,minecraft:air)
B(-5,20,-3,minecraft:air)
B(-5,20,-2,minecraft:air)
B(-5,21,-5,minecraft:spruce_log[axis=x])
B(-5,21,-4,minecraft:air)
B(-5,21,-3,minecraft:air)
B(-5,21,-2,minecraft:air)
B(-5,21,-1,minecraft:spruce_log[axis=x])
B(-5,22,-11,minecraft:grass_block)
B(-5,22,-10,minecraft:stone)
B(-5,22,-9,minecraft:stone)
B(-5,22,-8,minecraft:stone)
B(-5,22,-7,minecraft:stone)
B(-5,22,-6,minecraft:stone)
B(-5,22,-5,minecraft:stone)
B(-5,22,-4,minecraft:air)
B(-5,22,-3,minecraft:air)
B(-5,22,-2,minecraft:air)
B(-5,22,-1,minecraft:oak_fence)
B(-5,22,0,minecraft:stone)
B(-5,22,1,minecraft:stone)
B(-5,22,2,minecraft:stone)
B(-5,22,3,minecraft:stone)
B(-5,22,4,minecraft:stone)
B(-5,22,5,minecraft:stone)
B(-5,22,6,minecraft:stone)
B(-5,22,7,minecraft:stone)
B(-5,22,8,minecraft:stone)
B(-5,22,9,minecraft:stone)
B(-5,22,10,minecraft:grass_block)
B(-5,22,11,minecraft:grass_block)
B(-5,22,12,minecraft:grass_block)
B(-5,23,-10,minecraft:stone)
B(-5,23,-9,minecraft:stone)
B(-5,23,-8,minecraft:stone)
B(-5,23,-7,minecraft:stone)
B(-5,23,-6,minecraft:stone)
B(-5,23,-5,minecraft:stone)
B(-5,23,-4,minecraft:stone)
B(-5,23,-3,minecraft:stone)
B(-5,23,-2,minecraft:stone)
B(-5,23,-1,minecraft:stone)
B(-5,23,0,minecraft:stone)
B(-5,23,1,minecraft:stone)
B(-5,23,2,minecraft:stone)
B(-5,23,3,minecraft:stone)
B(-5,23,4,minecraft:stone)
B(-5,23,5,minecraft:stone)
B(-5,23,6,minecraft:stone)
B(-5,23,7,minecraft:stone)
B(-5,23,8,minecraft:stone)
B(-5,23,9,minecraft:stone)
B(-5,24,-10,minecraft:grass_block)
B(-5,24,-9,minecraft:stone)
B(-5,24,-8,minecraft:stone)
B(-5,24,-7,minecraft:stone)
B(-5,24,-6,minecraft:stone)
B(-5,24,-5,minecraft:stone)
B(-5,24,-4,minecraft:stone)
B(-5,24,-3,minecraft:stone)
B(-5,24,-2,minecraft:stone)
B(-5,24,-1,minecraft:stone)
B(-5,24,0,minecraft:stone)
B(-5,24,1,minecraft:stone)
B(-5,24,2,minecraft:stone)
B(-5,24,3,minecraft:stone)
B(-5,24,4,minecraft:stone)
B(-5,24,5,minecraft:stone)
B(-5,24,6,minecraft:stone)
B(-5,24,7,minecraft:stone)
B(-5,24,8,minecraft:stone)
B(-5,24,9,minecraft:stone)
B(-5,25,-9,minecraft:grass_block)
B(-5,25,-8,minecraft:stone)
B(-5,25,-7,minecraft:stone)
B(-5,25,-6,minecraft:stone)
B(-5,25,-5,minecraft:stone)
B(-5,25,-4,minecraft:stone)
B(-5,25,-3,minecraft:stone)
B(-5,25,-2,minecraft:stone)
B(-5,25,-1,minecraft:spruce_log[axis=x])
B(-5,25,0,minecraft:rail[shape=ascending_east])
B(-5,25,1,minecraft:cobblestone_stairs[facing=east,half=bottom,shape=straight,waterlogged=false])
B(-5,25,2,minecraft:rail[shape=ascending_east])
B(-5,25,3,minecraft:spruce_log[axis=x])
B(-5,25,4,minecraft:stone)
B(-5,25,5,minecraft:stone)
B(-5,25,6,minecraft:stone)
B(-5,25,7,minecraft:stone)
B(-5,25,8,minecraft:stone)
B(-5,25,9,minecraft:grass_block)
B(-5,26,-8,minecraft:stone)
B(-5,26,-7,minecraft:stone)
B(-5,26,-6,minecraft:stone)
B(-5,26,-5,minecraft:stone)
B(-5,26,-4,minecraft:stone)
B(-5,26,-3,minecraft:stone)
B(-5,26,-2,minecraft:stone)
B(-5,26,-1,minecraft:spruce_log)
B(-5,26,0,minecraft:air)
B(-5,26,1,minecraft:air)
B(-5,26,2,minecraft:air)
B(-5,26,3,minecraft:spruce_log)
B(-5,26,4,minecraft:stone)
B(-5,26,5,minecraft:stone)
B(-5,26,6,minecraft:stone)
B(-5,26,7,minecraft:stone)
B(-5,26,8,minecraft:stone)
B(-5,27,-8,minecraft:grass_block)
B(-5,27,-7,minecraft:stone)
B(-5,27,-6,minecraft:stone)
B(-5,27,-5,minecraft:stone)
B(-5,27,-4,minecraft:stone)
B(-5,27,-3,minecraft:stone)
B(-5,27,-2,minecraft:stone)
B(-5,27,-1,minecraft:spruce_log)
B(-5,27,0,minecraft:air)
B(-5,27,1,minecraft:air)
B(-5,27,2,minecraft:air)
B(-5,27,3,minecraft:spruce_log)
B(-5,27,4,minecraft:stone)
B(-5,27,5,minecraft:stone)
B(-5,27,6,minecraft:stone)
B(-5,27,7,minecraft:stone)
B(-5,27,8,minecraft:grass_block)
B(-5,28,-7,minecraft:grass_block)
B(-5,28,-6,minecraft:stone)
B(-5,28,-5,minecraft:stone)
B(-5,28,-4,minecraft:stone)
B(-5,28,-3,minecraft:stone)
B(-5,28,-2,minecraft:stone)
B(-5,28,-1,minecraft:spruce_log)
B(-5,28,3,minecraft:spruce_log)
B(-5,28,4,minecraft:stone)
B(-5,28,5,minecraft:stone)
B(-5,28,6,minecraft:stone)
B(-5,28,7,minecraft:stone)
B(-5,29,-6,minecraft:stone)
B(-5,29,-5,minecraft:stone)
B(-5,29,-4,minecraft:stone)
B(-5,29,-3,minecraft:stone)
B(-5,29,-2,minecraft:stone)
B(-5,29,-1,minecraft:stone)
B(-5,29,0,minecraft:spruce_log[axis=z])
B(-5,29,1,minecraft:spruce_log[axis=z])
B(-5,29,2,minecraft:spruce_log[axis=z])
B(-5,29,3,minecraft:stone)
B(-5,29,4,minecraft:stone)
B(-5,29,5,minecraft:stone)
B(-5,29,6,minecraft:stone)
B(-5,29,7,minecraft:stone)
B(-5,30,-6,minecraft:stone)
B(-5,30,-5,minecraft:stone)
B(-5,30,-4,minecraft:stone)
B(-5,30,-3,minecraft:stone)
B(-5,30,-2,minecraft:stone)
B(-5,30,-1,minecraft:stone)
B(-5,30,0,minecraft:stone)
B(-5,30,1,minecraft:stone)
B(-5,30,2,minecraft:stone)
B(-5,30,3,minecraft:stone)
B(-5,30,4,minecraft:stone)
B(-5,30,5,minecraft:stone)
B(-5,30,6,minecraft:stone)
B(-5,30,7,minecraft:grass_block)
B(-5,31,-6,minecraft:grass_block)
B(-5,31,-5,minecraft:stone)
B(-5,31,-4,minecraft:stone)
B(-5,31,-3,minecraft:stone)
B(-5,31,-2,minecraft:stone)
B(-5,31,-1,minecraft:stone)
B(-5,31,0,minecraft:stone)
B(-5,31,1,minecraft:stone)
B(-5,31,2,minecraft:stone)
B(-5,31,3,minecraft:stone)
B(-5,31,4,minecraft:stone)
B(-5,31,5,minecraft:stone)
B(-5,31,6,minecraft:stone)
B(-5,32,-5,minecraft:grass_block)
B(-5,32,-4,minecraft:grass_block)
B(-5,32,-3,minecraft:grass_block)
B(-5,32,-2,minecraft:grass_block)
B(-5,32,-1,minecraft:grass_block)
B(-5,32,0,minecraft:dirt)
B(-5,32,1,minecraft:stone)
B(-5,32,2,minecraft:stone)
B(-5,32,3,minecraft:stone)
B(-5,32,4,minecraft:stone)
B(-5,32,5,minecraft:grass_block)
B(-5,32,6,minecraft:grass_block)
B(-5,33,0,minecraft:grass_block)
B(-5,33,1,minecraft:grass_block)
B(-5,33,2,minecraft:grass_block)
B(-5,33,3,minecraft:grass_block)
B(-5,33,4,minecraft:grass_block)
B(-4,3,-4,minecraft:air)
B(-4,3,-3,minecraft:air)
B(-4,3,-2,minecraft:air)
B(-4,3,-1,minecraft:air)
B(-4,3,0,minecraft:air)
B(-4,3,1,minecraft:air)
B(-4,3,2,minecraft:air)
B(-4,3,3,minecraft:air)
B(-4,3,4,minecraft:air)
B(-4,4,-4,minecraft:air)
B(-4,4,-3,minecraft:air)
B(-4,4,-2,minecraft:air)
B(-4,4,-1,minecraft:air)
B(-4,4,0,minecraft:air)
B(-4,4,1,minecraft:air)
B(-4,4,2,minecraft:air)
B(-4,4,3,minecraft:air)
B(-4,4,4,minecraft:air)
B(-4,5,-4,minecraft:air)
B(-4,5,-3,minecraft:air)
B(-4,5,-2,minecraft:air)
B(-4,5,-1,minecraft:spruce_log[axis=x])
B(-4,5,0,minecraft:air)
B(-4,5,1,minecraft:air)
B(-4,5,2,minecraft:air)
B(-4,5,3,minecraft:air)
B(-4,16,-5,minecraft:spruce_log[axis=x])
B(-4,16,-4,minecraft:stone)
B(-4,16,-2,minecraft:stone)
B(-4,16,-1,minecraft:spruce_log[axis=x])
B(-4,17,-4,minecraft:stone)
B(-4,17,-3,minecraft:stone)
B(-4,17,-2,minecraft:stone)
B(-4,18,-4,minecraft:rail[shape=ascending_west])
B(-4,18,-3,minecraft:cobblestone_stairs[facing=west,half=bottom,shape=straight,waterlogged=false])
B(-4,18,-2,minecraft:rail[shape=ascending_west])
B(-4,19,-4,minecraft:air)
B(-4,19,-3,minecraft:air)
B(-4,19,-2,minecraft:air)
B(-4,20,-4,minecraft:air)
B(-4,20,-3,minecraft:air)
B(-4,20,-2,minecraft:air)
B(-4,21,-5,minecraft:spruce_log[axis=x])
B(-4,21,-4,minecraft:air)
B(-4,21,-3,minecraft:wall_torch[facing=west])
B(-4,21,-2,minecraft:air)
B(-4,21,-1,minecraft:spruce_log[axis=x])
B(-4,22,-11,minecraft:grass_block)
B(-4,22,-10,minecraft:stone)
B(-4,22,-9,minecraft:stone)
B(-4,22,-8,minecraft:stone)
B(-4,22,-7,minecraft:stone)
B(-4,22,-6,minecraft:stone)
B(-4,22,-5,minecraft:stone)
B(-4,22,-4,minecraft:stone)
B(-4,22,-3,minecraft:stone)
B(-4,22,-2,minecraft:stone)
B(-4,22,-1,minecraft:stone)
B(-4,22,0,minecraft:stone)
B(-4,22,1,minecraft:stone)
B(-4,22,2,minecraft:stone)
B(-4,22,3,minecraft:stone)
B(-4,22,4,minecraft:stone)
B(-4,22,5,minecraft:stone)
B(-4,22,6,minecraft:stone)
B(-4,22,7,minecraft:stone)
B(-4,22,8,minecraft:stone)
B(-4,22,9,minecraft:stone)
B(-4,22,10,minecraft:stone)
B(-4,22,11,minecraft:grass_block)
B(-4,22,12,minecraft:grass_block)
B(-4,23,-10,minecraft:stone)
B(-4,23,-9,minecraft:stone)
B(-4,23,-8,minecraft:stone)
B(-4,23,-7,minecraft:stone)
B(-4,23,-6,minecraft:stone)
B(-4,23,-5,minecraft:stone)
B(-4,23,-4,minecraft:stone)
B(-4,23,-3,minecraft:stone)
B(-4,23,-2,minecraft:stone)
B(-4,23,-1,minecraft:stone)
B(-4,23,0,minecraft:stone)
B(-4,23,1,minecraft:stone)
B(-4,23,2,minecraft:stone)
B(-4,23,3,minecraft:stone)
B(-4,23,4,minecraft:stone)
B(-4,23,5,minecraft:stone)
B(-4,23,6,minecraft:stone)
B(-4,23,7,minecraft:stone)
B(-4,23,8,minecraft:stone)
B(-4,23,9,minecraft:stone)
B(-4,23,10,minecraft:stone)
B(-4,24,-10,minecraft:grass_block)
B(-4,24,-9,minecraft:stone)
B(-4,24,-8,minecraft:stone)
B(-4,24,-7,minecraft:stone)
B(-4,24,-6,minecraft:stone)
B(-4,24,-5,minecraft:stone)
B(-4,24,-4,minecraft:stone)
B(-4,24,-3,minecraft:stone)
B(-4,24,-2,minecraft:stone)
B(-4,24,-1,minecraft:stone)
B(-4,24,0,minecraft:stone)
B(-4,24,1,minecraft:stone)
B(-4,24,2,minecraft:stone)
B(-4,24,3,minecraft:stone)
B(-4,24,4,minecraft:stone)
B(-4,24,5,minecraft:stone)
B(-4,24,6,minecraft:stone)
B(-4,24,7,minecraft:stone)
B(-4,24,8,minecraft:stone)
B(-4,24,9,minecraft:stone)
B(-4,24,10,minecraft:stone)
B(-4,25,-9,minecraft:stone)
B(-4,25,-8,minecraft:stone)
B(-4,25,-7,minecraft:stone)
B(-4,25,-6,minecraft:stone)
B(-4,25,-5,minecraft:stone)
B(-4,25,-4,minecraft:stone)
B(-4,25,-3,minecraft:stone)
B(-4,25,-2,minecraft:stone)
B(-4,25,-1,minecraft:stone)
B(-4,25,0,minecraft:stone)
B(-4,25,1,minecraft:stone)
B(-4,25,2,minecraft:stone)
B(-4,25,3,minecraft:stone)
B(-4,25,4,minecraft:stone)
B(-4,25,5,minecraft:stone)
B(-4,25,6,minecraft:stone)
B(-4,25,7,minecraft:stone)
B(-4,25,8,minecraft:stone)
B(-4,25,9,minecraft:stone)
B(-4,25,10,minecraft:stone)
B(-4,26,-9,minecraft:grass_block)
B(-4,26,-8,minecraft:stone)
B(-4,26,-7,minecraft:stone)
B(-4,26,-6,minecraft:stone)
B(-4,26,-5,minecraft:stone)
B(-4,26,-4,minecraft:stone)
B(-4,26,-3,minecraft:stone)
B(-4,26,-2,minecraft:stone)
B(-4,26,-1,minecraft:stone)
B(-4,26,0,minecraft:rail[shape=ascending_east])
B(-4,26,1,minecraft:cobblestone_stairs[facing=east,half=bottom,shape=straight,waterlogged=false])
B(-4,26,2,minecraft:rail[shape=ascending_east])
B(-4,26,3,minecraft:stone)
B(-4,26,4,minecraft:stone)
B(-4,26,5,minecraft:stone)
B(-4,26,6,minecraft:stone)
B(-4,26,7,minecraft:stone)
B(-4,26,8,minecraft:stone)
B(-4,26,9,minecraft:stone)
B(-4,26,10,minecraft:grass_block)
B(-4,27,-8,minecraft:grass_block)
B(-4,27,-7,minecraft:stone)
B(-4,27,-6,minecraft:stone)
B(-4,27,-5,minecraft:stone)
B(-4,27,-4,minecraft:stone)
B(-4,27,-3,minecraft:stone)
B(-4,27,-2,minecraft:stone)
B(-4,27,-1,minecraft:oak_fence)
B(-4,27,0,minecraft:air)
B(-4,27,1,minecraft:air)
B(-4,27,2,minecraft:air)
B(-4,27,3,minecraft:stone)
B(-4,27,4,minecraft:stone)
B(-4,27,5,minecraft:stone)
B(-4,27,6,minecraft:stone)
B(-4,27,7,minecraft:stone)
B(-4,27,8,minecraft:stone)
B(-4,27,9,minecraft:grass_block)
B(-4,28,-7,minecraft:stone)
B(-4,28,-6,minecraft:stone)
B(-4,28,-5,minecraft:stone)
B(-4,28,-4,minecraft:stone)
B(-4,28,-3,minecraft:stone)
B(-4,28,-2,minecraft:stone)
B(-4,28,-1,minecraft:oak_fence)
B(-4,28,3,minecraft:stone)
B(-4,28,4,minecraft:stone)
B(-4,28,5,minecraft:stone)
B(-4,28,6,minecraft:stone)
B(-4,28,7,minecraft:stone)
B(-4,28,8,minecraft:stone)
B(-4,29,-7,minecraft:grass_block)
B(-4,29,-6,minecraft:grass_block)
B(-4,29,-5,minecraft:stone)
B(-4,29,-4,minecraft:stone)
B(-4,29,-3,minecraft:stone)
B(-4,29,-2,minecraft:stone)
B(-4,29,-1,minecraft:stone)
B(-4,29,3,minecraft:stone)
B(-4,29,4,minecraft:stone)
B(-4,29,5,minecraft:stone)
B(-4,29,6,minecraft:stone)
B(-4,29,7,minecraft:grass_block)
B(-4,29,8,minecraft:grass_block)
B(-4,30,-5,minecraft:stone)
B(-4,30,-4,minecraft:stone)
B(-4,30,-3,minecraft:stone)
B(-4,30,-2,minecraft:stone)
B(-4,30,-1,minecraft:stone)
B(-4,30,0,minecraft:stone)
B(-4,30,1,minecraft:stone)
B(-4,30,2,minecraft:stone)
B(-4,30,3,minecraft:stone)
B(-4,30,4,minecraft:stone)
B(-4,30,5,minecraft:stone)
B(-4,30,6,minecraft:stone)
B(-4,31,-5,minecraft:grass_block)
B(-4,31,-4,minecraft:stone)
B(-4,31,-3,minecraft:stone)
B(-4,31,-2,minecraft:stone)
B(-4,31,-1,minecraft:stone)
B(-4,31,0,minecraft:stone)
B(-4,31,1,minecraft:stone)
B(-4,31,2,minecraft:stone)
B(-4,31,3,minecraft:stone)
B(-4,31,4,minecraft:stone)
B(-4,31,5,minecraft:stone)
B(-4,31,6,minecraft:stone)
B(-4,32,-4,minecraft:grass_block)
B(-4,32,-3,minecraft:grass_block)
B(-4,32,-2,minecraft:grass_block)
B(-4,32,-1,minecraft:grass_block)
B(-4,32,0,minecraft:grass_block)
B(-4,32,1,minecraft:grass_block)
B(-4,32,2,minecraft:stone)
B(-4,32,3,minecraft:stone)
B(-4,32,4,minecraft:stone)
B(-4,32,5,minecraft:stone)
B(-4,32,6,minecraft:grass_block)
B(-4,33,2,minecraft:grass_block)
B(-4,33,3,minecraft:grass_block)
B(-4,33,4,minecraft:grass_block)
B(-4,33,5,minecraft:grass_block)
B(-3,3,-5,minecraft:air)
B(-3,3,-4,minecraft:air)
B(-3,3,-3,minecraft:air)
B(-3,3,-2,minecraft:air)
B(-3,3,-1,minecraft:air)
B(-3,3,0,minecraft:air)
B(-3,3,1,minecraft:air)
B(-3,3,2,minecraft:air)
B(-3,3,3,minecraft:air)
B(-3,3,4,minecraft:air)
B(-3,4,-5,minecraft:air)
B(-3,4,-4,minecraft:air)
B(-3,4,-3,minecraft:air)
B(-3,4,-2,minecraft:air)
B(-3,4,-1,minecraft:air)
B(-3,4,0,minecraft:air)
B(-3,4,1,minecraft:air)
B(-3,4,2,minecraft:air)
B(-3,4,3,minecraft:air)
B(-3,4,4,minecraft:air)
B(-3,5,-5,minecraft:air)
B(-3,5,-4,minecraft:air)
B(-3,5,-3,minecraft:air)
B(-3,5,-2,minecraft:air)
B(-3,5,-1,minecraft:spruce_log[axis=x])
B(-3,5,0,minecraft:air)
B(-3,5,1,minecraft:air)
B(-3,5,2,minecraft:air)
B(-3,5,3,minecraft:air)
B(-3,5,4,minecraft:air)
B(-3,6,-2,minecraft:air)
B(-3,6,0,minecraft:air)
B(-3,6,1,minecraft:air)
B(-3,6,2,minecraft:air)
B(-3,6,3,minecraft:air)
B(-3,15,-4,minecraft:stone)
B(-3,15,-2,minecraft:stone)
B(-3,16,-5,minecraft:spruce_log[axis=x])
B(-3,16,-4,minecraft:stone)
B(-3,16,-3,minecraft:stone)
B(-3,16,-2,minecraft:stone)
B(-3,16,-1,minecraft:spruce_log[axis=x])
B(-3,17,-5,minecraft:spruce_log)
B(-3,17,-4,minecraft:rail[shape=ascending_west])
B(-3,17,-3,minecraft:cobblestone_stairs[facing=west,half=bottom,shape=straight,waterlogged=false])
B(-3,17,-2,minecraft:rail[shape=ascending_west])
B(-3,17,-1,minecraft:spruce_log)
B(-3,18,-5,minecraft:spruce_log)
B(-3,18,-4,minecraft:air)
B(-3,18,-3,minecraft:air)
B(-3,18,-2,minecraft:air)
B(-3,18,-1,minecraft:spruce_log)
B(-3,19,-5,minecraft:spruce_log)
B(-3,19,-4,minecraft:air)
B(-3,19,-3,minecraft:air)
B(-3,19,-2,minecraft:air)
B(-3,19,-1,minecraft:spruce_log)
B(-3,20,-5,minecraft:spruce_log)
B(-3,20,-4,minecraft:air)
B(-3,20,-3,minecraft:air)
B(-3,20,-2,minecraft:air)
B(-3,20,-1,minecraft:spruce_log)
B(-3,21,-4,minecraft:spruce_log[axis=z])
B(-3,21,-3,minecraft:spruce_log[axis=z])
B(-3,21,-2,minecraft:spruce_log[axis=z])
B(-3,22,-11,minecraft:grass_block)
B(-3,22,-10,minecraft:stone)
B(-3,22,-9,minecraft:stone)
B(-3,22,-8,minecraft:stone)
B(-3,22,-7,minecraft:stone)
B(-3,22,-6,minecraft:stone)
B(-3,22,-5,minecraft:stone)
B(-3,22,-4,minecraft:stone)
B(-3,22,-3,minecraft:stone)
B(-3,22,-2,minecraft:stone)
B(-3,22,-1,minecraft:stone)
B(-3,22,0,minecraft:stone)
B(-3,22,1,minecraft:stone)
B(-3,22,2,minecraft:stone)
B(-3,22,3,minecraft:stone)
B(-3,22,4,minecraft:stone)
B(-3,22,5,minecraft:stone)
B(-3,22,6,minecraft:stone)
B(-3,22,7,minecraft:stone)
B(-3,22,8,minecraft:stone)
B(-3,22,9,minecraft:stone)
B(-3,22,10,minecraft:stone)
B(-3,22,11,minecraft:stone)
B(-3,22,12,minecraft:grass_block)
B(-3,23,-10,minecraft:stone)
B(-3,23,-9,minecraft:stone)
B(-3,23,-8,minecraft:stone)
B(-3,23,-7,minecraft:stone)
B(-3,23,-6,minecraft:stone)
B(-3,23,-5,minecraft:stone)
B(-3,23,-4,minecraft:stone)
B(-3,23,-3,minecraft:stone)
B(-3,23,-2,minecraft:stone)
B(-3,23,-1,minecraft:stone)
B(-3,23,0,minecraft:stone)
B(-3,23,1,minecraft:stone)
B(-3,23,2,minecraft:stone)
B(-3,23,3,minecraft:stone)
B(-3,23,4,minecraft:stone)
B(-3,23,5,minecraft:stone)
B(-3,23,6,minecraft:stone)
B(-3,23,7,minecraft:stone)
B(-3,23,8,minecraft:stone)
B(-3,23,9,minecraft:stone)
B(-3,23,10,minecraft:stone)
B(-3,23,11,minecraft:stone)
B(-3,24,-10,minecraft:stone)
B(-3,24,-9,minecraft:stone)
B(-3,24,-8,minecraft:stone)
B(-3,24,-7,minecraft:stone)
B(-3,24,-6,minecraft:stone)
B(-3,24,-5,minecraft:stone)
B(-3,24,-4,minecraft:stone)
B(-3,24,-3,minecraft:stone)
B(-3,24,-2,minecraft:stone)
B(-3,24,-1,minecraft:stone)
B(-3,24,0,minecraft:stone)
B(-3,24,1,minecraft:stone)
B(-3,24,2,minecraft:stone)
B(-3,24,3,minecraft:stone)
B(-3,24,4,minecraft:stone)
B(-3,24,5,minecraft:stone)
B(-3,24,6,minecraft:stone)
B(-3,24,7,minecraft:stone)
B(-3,24,8,minecraft:stone)
B(-3,24,9,minecraft:stone)
B(-3,24,10,minecraft:stone)
B(-3,24,11,minecraft:stone)
B(-3,25,-10,minecraft:stone)
B(-3,25,-9,minecraft:stone)
B(-3,25,-8,minecraft:stone)
B(-3,25,-7,minecraft:stone)
B(-3,25,-6,minecraft:stone)
B(-3,25,-5,minecraft:stone)
B(-3,25,-4,minecraft:stone)
B(-3,25,-3,minecraft:stone)
B(-3,25,-2,minecraft:stone)
B(-3,25,-1,minecraft:stone)
B(-3,25,0,minecraft:stone)
B(-3,25,1,minecraft:stone)
B(-3,25,2,minecraft:stone)
B(-3,25,3,minecraft:stone)
B(-3,25,4,minecraft:stone)
B(-3,25,5,minecraft:stone)
B(-3,25,6,minecraft:stone)
B(-3,25,7,minecraft:stone)
B(-3,25,8,minecraft:stone)
B(-3,25,9,minecraft:stone)
B(-3,25,10,minecraft:stone)
B(-3,25,11,minecraft:grass_block)
B(-3,26,-10,minecraft:grass_block)
B(-3,26,-9,minecraft:stone)
B(-3,26,-8,minecraft:stone)
B(-3,26,-7,minecraft:stone)
B(-3,26,-6,minecraft:stone)
B(-3,26,-5,minecraft:stone)
B(-3,26,-4,minecraft:stone)
B(-3,26,-3,minecraft:stone)
B(-3,26,-2,minecraft:stone)
B(-3,26,-1,minecraft:stone)
B(-3,26,0,minecraft:stone)
B(-3,26,1,minecraft:stone)
B(-3,26,2,minecraft:stone)
B(-3,26,3,minecraft:stone)
B(-3,26,4,minecraft:stone)
B(-3,26,5,minecraft:stone)
B(-3,26,6,minecraft:stone)
B(-3,26,7,minecraft:stone)
B(-3,26,8,minecraft:stone)
B(-3,26,9,minecraft:stone)
B(-3,26,10,minecraft:stone)
B(-3,27,-9,minecraft:grass_block)
B(-3,27,-8,minecraft:stone)
B(-3,27,-7,minecraft:stone)
B(-3,27,-6,minecraft:stone)
B(-3,27,-5,minecraft:stone)
B(-3,27,-4,minecraft:stone)
B(-3,27,-3,minecraft:stone)
B(-3,27,-2,minecraft:stone)
B(-3,27,-1,minecraft:stone)
B(-3,27,0,minecraft:rail[shape=ascending_east])
B(-3,27,1,minecraft:cobblestone_stairs[facing=east,half=bottom,shape=straight,waterlogged=false])
B(-3,27,2,minecraft:rail[shape=ascending_east])
B(-3,27,3,minecraft:stone)
B(-3,27,4,minecraft:stone)
B(-3,27,5,minecraft:stone)
B(-3,27,6,minecraft:stone)
B(-3,27,7,minecraft:stone)
B(-3,27,8,minecraft:stone)
B(-3,27,9,minecraft:stone)
B(-3,27,10,minecraft:stone)
B(-3,28,-8,minecraft:grass_block)
B(-3,28,-7,minecraft:stone)
B(-3,28,-6,minecraft:stone)
B(-3,28,-5,minecraft:stone)
B(-3,28,-4,minecraft:stone)
B(-3,28,-3,minecraft:stone)
B(-3,28,-2,minecraft:stone)
B(-3,28,-1,minecraft:stone)
B(-3,28,3,minecraft:stone)
B(-3,28,4,minecraft:stone)
B(-3,28,5,minecraft:stone)
B(-3,28,6,minecraft:stone)
B(-3,28,7,minecraft:stone)
B(-3,28,8,minecraft:stone)
B(-3,28,9,minecraft:stone)
B(-3,28,10,minecraft:grass_block)
B(-3,29,-7,minecraft:grass_block)
B(-3,29,-6,minecraft:grass_block)
B(-3,29,-5,minecraft:stone)
B(-3,29,-4,minecraft:stone)
B(-3,29,-3,minecraft:stone)
B(-3,29,-2,minecraft:stone)
B(-3,29,-1,minecraft:stone)
B(-3,29,3,minecraft:stone)
B(-3,29,4,minecraft:stone)
B(-3,29,5,minecraft:stone)
B(-3,29,6,minecraft:stone)
B(-3,29,7,minecraft:stone)
B(-3,29,8,minecraft:grass_block)
B(-3,29,9,minecraft:grass_block)
B(-3,30,-5,minecraft:stone)
B(-3,30,-4,minecraft:stone)
B(-3,30,-3,minecraft:stone)
B(-3,30,-2,minecraft:stone)
B(-3,30,-1,minecraft:stone)
B(-3,30,0,minecraft:stone)
B(-3,30,1,minecraft:stone)
B(-3,30,2,minecraft:stone)
B(-3,30,3,minecraft:stone)
B(-3,30,4,minecraft:stone)
B(-3,30,5,minecraft:stone)
B(-3,30,6,minecraft:stone)
B(-3,30,7,minecraft:grass_block)
B(-3,31,-5,minecraft:grass_block)
B(-3,31,-4,minecraft:stone)
B(-3,31,-3,minecraft:stone)
B(-3,31,-2,minecraft:stone)
B(-3,31,-1,minecraft:stone)
B(-3,31,0,minecraft:stone)
B(-3,31,1,minecraft:stone)
B(-3,31,2,minecraft:stone)
B(-3,31,3,minecraft:stone)
B(-3,31,4,minecraft:stone)
B(-3,31,5,minecraft:stone)
B(-3,31,6,minecraft:stone)
B(-3,32,-4,minecraft:grass_block)
B(-3,32,-2,minecraft:grass_block)
B(-3,32,1,minecraft:grass_block)
B(-3,32,2,minecraft:grass_block)
B(-3,32,3,minecraft:dirt)
B(-3,32,4,minecraft:grass_block)
B(-3,32,5,minecraft:grass_block)
B(-3,32,6,minecraft:grass_block)
B(-3,33,3,minecraft:grass_block)
B(-2,3,-6,minecraft:air)
B(-2,3,-5,minecraft:air)
B(-2,3,-4,minecraft:air)
B(-2,3,-3,minecraft:air)
B(-2,3,-2,minecraft:air)
B(-2,3,-1,minecraft:air)
B(-2,3,0,minecraft:air)
B(-2,3,1,minecraft:air)
B(-2,3,2,minecraft:air)
B(-2,3,3,minecraft:air)
B(-2,3,4,minecraft:air)
B(-2,4,-6,minecraft:air)
B(-2,4,-5,minecraft:air)
B(-2,4,-4,minecraft:air)
B(-2,4,-3,minecraft:air)
B(-2,4,-2,minecraft:air)
B(-2,4,-1,minecraft:air)
B(-2,4,0,minecraft:air)
B(-2,4,1,minecraft:air)
B(-2,4,2,minecraft:air)
B(-2,4,3,minecraft:air)
B(-2,4,4,minecraft:air)
B(-2,5,-6,minecraft:air)
B(-2,5,-5,minecraft:air)
B(-2,5,-4,minecraft:air)
B(-2,5,-3,minecraft:air)
B(-2,5,-2,minecraft:air)
B(-2,5,-1,minecraft:spruce_log[axis=x])
B(-2,5,0,minecraft:air)
B(-2,5,1,minecraft:air)
B(-2,5,2,minecraft:air)
B(-2,5,3,minecraft:air)
B(-2,5,4,minecraft:air)
B(-2,6,-7,minecraft:air)
B(-2,6,-6,minecraft:air)
B(-2,6,-5,minecraft:air)
B(-2,6,-2,minecraft:air)
B(-2,6,0,minecraft:air)
B(-2,6,1,minecraft:air)
B(-2,6,2,minecraft:air)
B(-2,14,-4,minecraft:stone)
B(-2,14,-2,minecraft:stone)
B(-2,15,-4,minecraft:stone)
B(-2,15,-3,minecraft:stone)
B(-2,15,-2,minecraft:stone)
B(-2,16,-5,minecraft:spruce_log[axis=x])
B(-2,16,-4,minecraft:rail[shape=ascending_west])
B(-2,16,-3,minecraft:cobblestone_stairs[facing=west,half=bottom,shape=straight,waterlogged=false])
B(-2,16,-2,minecraft:rail[shape=ascending_west])
B(-2,16,-1,minecraft:spruce_log[axis=x])
B(-2,17,-5,minecraft:oak_fence)
B(-2,17,-4,minecraft:air)
B(-2,17,-3,minecraft:air)
B(-2,17,-2,minecraft:air)
B(-2,17,-1,minecraft:oak_fence)
B(-2,18,-5,minecraft:oak_fence)
B(-2,18,-4,minecraft:air)
B(-2,18,-3,minecraft:air)
B(-2,18,-2,minecraft:air)
B(-2,18,-1,minecraft:oak_fence)
B(-2,19,-4,minecraft:air)
B(-2,19,-3,minecraft:air)
B(-2,19,-2,minecraft:air)
B(-2,22,-11,minecraft:grass_block)
B(-2,22,-10,minecraft:stone)
B(-2,22,-9,minecraft:stone)
B(-2,22,-8,minecraft:stone)
B(-2,22,-7,minecraft:stone)
B(-2,22,-6,minecraft:stone)
B(-2,22,-5,minecraft:stone)
B(-2,22,-4,minecraft:stone)
B(-2,22,-3,minecraft:stone)
B(-2,22,-2,minecraft:stone)
B(-2,22,-1,minecraft:stone)
B(-2,22,0,minecraft:stone)
B(-2,22,1,minecraft:stone)
B(-2,22,2,minecraft:stone)
B(-2,22,3,minecraft:stone)
B(-2,22,4,minecraft:stone)
B(-2,22,5,minecraft:stone)
B(-2,22,6,minecraft:stone)
B(-2,22,7,minecraft:stone)
B(-2,22,8,minecraft:stone)
B(-2,22,9,minecraft:stone)
B(-2,22,10,minecraft:stone)
B(-2,22,11,minecraft:stone)
B(-2,22,12,minecraft:grass_block)
B(-2,23,-10,minecraft:stone)
B(-2,23,-9,minecraft:stone)
B(-2,23,-8,minecraft:stone)
B(-2,23,-7,minecraft:stone)
B(-2,23,-6,minecraft:stone)
B(-2,23,-5,minecraft:stone)
B(-2,23,-4,minecraft:stone)
B(-2,23,-3,minecraft:stone)
B(-2,23,-2,minecraft:stone)
B(-2,23,-1,minecraft:stone)
B(-2,23,0,minecraft:stone)
B(-2,23,1,minecraft:stone)
B(-2,23,2,minecraft:stone)
B(-2,23,3,minecraft:stone)
B(-2,23,4,minecraft:stone)
B(-2,23,5,minecraft:stone)
B(-2,23,6,minecraft:stone)
B(-2,23,7,minecraft:stone)
B(-2,23,8,minecraft:stone)
B(-2,23,9,minecraft:stone)
B(-2,23,10,minecraft:stone)
B(-2,23,11,minecraft:stone)
B(-2,24,-10,minecraft:grass_block)
B(-2,24,-9,minecraft:stone)
B(-2,24,-8,minecraft:stone)
B(-2,24,-7,minecraft:stone)
B(-2,24,-6,minecraft:stone)
B(-2,24,-5,minecraft:stone)
B(-2,24,-4,minecraft:stone)
B(-2,24,-3,minecraft:stone)
B(-2,24,-2,minecraft:stone)
B(-2,24,-1,minecraft:stone)
B(-2,24,0,minecraft:stone)
B(-2,24,1,minecraft:stone)
B(-2,24,2,minecraft:stone)
B(-2,24,3,minecraft:stone)
B(-2,24,4,minecraft:stone)
B(-2,24,5,minecraft:stone)
B(-2,24,6,minecraft:stone)
B(-2,24,7,minecraft:stone)
B(-2,24,8,minecraft:stone)
B(-2,24,9,minecraft:stone)
B(-2,24,10,minecraft:stone)
B(-2,24,11,minecraft:grass_block)
B(-2,25,-9,minecraft:grass_block)
B(-2,25,-8,minecraft:stone)
B(-2,25,-7,minecraft:stone)
B(-2,25,-6,minecraft:stone)
B(-2,25,-5,minecraft:stone)
B(-2,25,-4,minecraft:stone)
B(-2,25,-3,minecraft:stone)
B(-2,25,-2,minecraft:stone)
B(-2,25,-1,minecraft:stone)
B(-2,25,0,minecraft:stone)
B(-2,25,1,minecraft:stone)
B(-2,25,2,minecraft:stone)
B(-2,25,3,minecraft:stone)
B(-2,25,4,minecraft:stone)
B(-2,25,5,minecraft:stone)
B(-2,25,6,minecraft:stone)
B(-2,25,7,minecraft:stone)
B(-2,25,8,minecraft:stone)
B(-2,25,9,minecraft:stone)
B(-2,25,10,minecraft:stone)
B(-2,26,-8,minecraft:stone)
B(-2,26,-7,minecraft:stone)
B(-2,26,-6,minecraft:stone)
B(-2,26,-5,minecraft:stone)
B(-2,26,-4,minecraft:stone)
B(-2,26,-3,minecraft:stone)
B(-2,26,-2,minecraft:stone)
B(-2,26,-1,minecraft:stone)
B(-2,26,0,minecraft:stone)
B(-2,26,1,minecraft:stone)
B(-2,26,2,minecraft:stone)
B(-2,26,3,minecraft:stone)
B(-2,26,4,minecraft:stone)
B(-2,26,5,minecraft:stone)
B(-2,26,6,minecraft:stone)
B(-2,26,7,minecraft:stone)
B(-2,26,8,minecraft:stone)
B(-2,26,9,minecraft:stone)
B(-2,26,10,minecraft:stone)
B(-2,27,-8,minecraft:stone)
B(-2,27,-7,minecraft:stone)
B(-2,27,-6,minecraft:stone)
B(-2,27,-5,minecraft:stone)
B(-2,27,-4,minecraft:stone)
B(-2,27,-3,minecraft:stone)
B(-2,27,-2,minecraft:stone)
B(-2,27,-1,minecraft:stone)
B(-2,27,0,minecraft:stone)
B(-2,27,1,minecraft:stone)
B(-2,27,2,minecraft:stone)
B(-2,27,3,minecraft:stone)
B(-2,27,4,minecraft:stone)
B(-2,27,5,minecraft:stone)
B(-2,27,6,minecraft:stone)
B(-2,27,7,minecraft:stone)
B(-2,27,8,minecraft:stone)
B(-2,27,9,minecraft:stone)
B(-2,27,10,minecraft:stone)
B(-2,28,-8,minecraft:grass_block)
B(-2,28,-7,minecraft:stone)
B(-2,28,-6,minecraft:stone)
B(-2,28,-5,minecraft:stone)
B(-2,28,-4,minecraft:stone)
B(-2,28,-3,minecraft:stone)
B(-2,28,-2,minecraft:stone)
B(-2,28,-1,minecraft:infested_cobblestone)
B(-2,28,0,minecraft:rail[shape=east_west])
B(-2,28,2,minecraft:rail[shape=east_west])
B(-2,28,3,minecraft:infested_cobblestone)
B(-2,28,4,minecraft:stone)
B(-2,28,5,minecraft:stone)
B(-2,28,6,minecraft:stone)
B(-2,28,7,minecraft:stone)
B(-2,28,8,minecraft:stone)
B(-2,28,9,minecraft:stone)
B(-2,28,10,minecraft:grass_block)
B(-2,29,-7,minecraft:grass_block)
B(-2,29,-6,minecraft:stone)
B(-2,29,-5,minecraft:stone)
B(-2,29,-4,minecraft:stone)
B(-2,29,-3,minecraft:stone)
B(-2,29,-2,minecraft:stone)
B(-2,29,-1,minecraft:infested_cobblestone)
B(-2,29,3,minecraft:infested_cobblestone)
B(-2,29,4,minecraft:stone)
B(-2,29,5,minecraft:stone)
B(-2,29,6,minecraft:stone)
B(-2,29,7,minecraft:stone)
B(-2,29,8,minecraft:stone)
B(-2,29,9,minecraft:stone)
B(-2,30,-6,minecraft:grass_block)
B(-2,30,-5,minecraft:stone)
B(-2,30,-4,minecraft:stone)
B(-2,30,-3,minecraft:stone)
B(-2,30,-2,minecraft:stone)
B(-2,30,-1,minecraft:infested_cobblestone)
B(-2,30,0,minecraft:infested_cobblestone)
B(-2,30,1,minecraft:infested_cobblestone)
B(-2,30,2,minecraft:infested_cobblestone)
B(-2,30,3,minecraft:infested_cobblestone)
B(-2,30,4,minecraft:stone)
B(-2,30,5,minecraft:stone)
B(-2,30,6,minecraft:stone)
B(-2,30,7,minecraft:stone)
B(-2,30,8,minecraft:stone)
B(-2,30,9,minecraft:grass_block)
B(-2,31,-5,minecraft:grass_block)
B(-2,31,-4,minecraft:stone)
B(-2,31,-3,minecraft:grass_block)
B(-2,31,-2,minecraft:stone)
B(-2,31,0,minecraft:stone)
B(-2,31,1,minecraft:stone)
B(-2,31,2,minecraft:stone)
B(-2,31,3,minecraft:stone)
B(-2,31,4,minecraft:stone)
B(-2,31,5,minecraft:stone)
B(-2,31,6,minecraft:stone)
B(-2,31,7,minecraft:stone)
B(-2,31,8,minecraft:grass_block)
B(-2,32,-2,minecraft:grass_block)
B(-2,32,1,minecraft:grass_block)
B(-2,32,2,minecraft:grass_block)
B(-2,32,3,minecraft:grass_block)
B(-2,32,4,minecraft:grass_block)
B(-2,32,5,minecraft:grass_block)
B(-2,32,6,minecraft:grass_block)
B(-2,32,7,minecraft:grass_block)
B(-1,0,-5,minecraft:spruce_log)
B(-1,0,-1,minecraft:spruce_log)
B(-1,0,2,minecraft:spruce_log)
B(-1,1,-5,minecraft:spruce_log)
B(-1,1,-1,minecraft:spruce_log)
B(-1,1,2,minecraft:spruce_log)
B(-1,2,-5,minecraft:spruce_log)
B(-1,2,-1,minecraft:spruce_log)
B(-1,2,2,minecraft:spruce_log)
B(-1,3,-6,minecraft:air)
B(-1,3,-5,minecraft:spruce_log)
B(-1,3,-4,minecraft:air)
B(-1,3,-3,minecraft:air)
B(-1,3,-2,minecraft:air)
B(-1,3,-1,minecraft:spruce_log)
B(-1,3,0,minecraft:air)
B(-1,3,1,minecraft:air)
B(-1,3,2,minecraft:spruce_log)
B(-1,3,3,minecraft:air)
B(-1,3,4,minecraft:air)
B(-1,4,-6,minecraft:air)
B(-1,4,-5,minecraft:spruce_log)
B(-1,4,-4,minecraft:air)
B(-1,4,-3,minecraft:air)
B(-1,4,-2,minecraft:wall_torch)
B(-1,4,-1,minecraft:spruce_log)
B(-1,4,0,minecraft:air)
B(-1,4,1,minecraft:air)
B(-1,4,2,minecraft:spruce_log)
B(-1,4,3,minecraft:air)
B(-1,4,4,minecraft:air)
B(-1,5,-7,minecraft:air)
B(-1,5,-6,minecraft:air)
B(-1,5,-5,minecraft:spruce_log)
B(-1,5,-4,minecraft:air)
B(-1,5,-3,minecraft:air)
B(-1,5,-2,minecraft:air)
B(-1,5,-1,minecraft:spruce_log)
B(-1,5,0,minecraft:air)
B(-1,5,1,minecraft:air)
B(-1,5,2,minecraft:spruce_log)
B(-1,5,3,minecraft:air)
B(-1,5,4,minecraft:air)
B(-1,6,-7,minecraft:air)
B(-1,6,-6,minecraft:air)
B(-1,6,-5,minecraft:spruce_log)
B(-1,6,-4,minecraft:spruce_log[axis=z])
B(-1,6,-3,minecraft:spruce_log[axis=z])
B(-1,6,-2,minecraft:spruce_log[axis=z])
B(-1,6,-1,minecraft:spruce_log)
B(-1,6,0,minecraft:spruce_log[axis=z])
B(-1,6,1,minecraft:spruce_log[axis=z])
B(-1,6,2,minecraft:spruce_log[axis=z])
B(-1,6,3,minecraft:air)
B(-1,7,-5,minecraft:spruce_log)
B(-1,7,-4,minecraft:air)
B(-1,7,-1,minecraft:spruce_log)
B(-1,8,-5,minecraft:spruce_log)
B(-1,8,-1,minecraft:spruce_log)
B(-1,9,-5,minecraft:spruce_log)
B(-1,9,-1,minecraft:spruce_log)
B(-1,10,-5,minecraft:spruce_log)
B(-1,10,-1,minecraft:spruce_log)
B(-1,11,-5,minecraft:spruce_log)
B(-1,11,-1,minecraft:spruce_log)
B(-1,12,-5,minecraft:spruce_log)
B(-1,12,-1,minecraft:spruce_log)
B(-1,13,-5,minecraft:spruce_log)
B(-1,13,-4,minecraft:stone)
B(-1,13,-2,minecraft:stone)
B(-1,13,-1,minecraft:spruce_log)
B(-1,14,-5,minecraft:spruce_log)
B(-1,14,-4,minecraft:stone)
B(-1,14,-3,minecraft:stone)
B(-1,14,-2,minecraft:stone)
B(-1,14,-1,minecraft:spruce_log)
B(-1,15,-5,minecraft:spruce_log)
B(-1,15,-4,minecraft:rail[shape=ascending_west])
B(-1,15,-3,minecraft:cobblestone_stairs[facing=west,half=bottom,shape=straight,waterlogged=false])
B(-1,15,-2,minecraft:rail[shape=ascending_west])
B(-1,15,-1,minecraft:spruce_log)
B(-1,16,-5,minecraft:spruce_log[axis=x])
B(-1,16,-4,minecraft:air)
B(-1,16,-3,minecraft:air)
B(-1,16,-2,minecraft:air)
B(-1,16,-1,minecraft:spruce_log[axis=x])
B(-1,17,-5,minecraft:oak_fence)
B(-1,17,-4,minecraft:air)
B(-1,17,-3,minecraft:air)
B(-1,17,-2,minecraft:air)
B(-1,17,-1,minecraft:oak_fence)
B(-1,18,-5,minecraft:oak_fence)
B(-1,18,-4,minecraft:air)
B(-1,18,-3,minecraft:air)
B(-1,18,-2,minecraft:air)
B(-1,18,-1,minecraft:oak_fence)
B(-1,22,-11,minecraft:grass_block)
B(-1,22,-10,minecraft:stone)
B(-1,22,-9,minecraft:stone)
B(-1,22,-8,minecraft:stone)
B(-1,22,-7,minecraft:stone)
B(-1,22,-6,minecraft:stone)
B(-1,22,-5,minecraft:stone)
B(-1,22,-4,minecraft:stone)
B(-1,22,-3,minecraft:stone)
B(-1,22,-2,minecraft:stone)
B(-1,22,-1,minecraft:stone)
B(-1,22,0,minecraft:stone)
B(-1,22,1,minecraft:stone)
B(-1,22,2,minecraft:stone)
B(-1,22,3,minecraft:stone)
B(-1,22,4,minecraft:stone)
B(-1,22,5,minecraft:stone)
B(-1,22,6,minecraft:stone)
B(-1,22,7,minecraft:stone)
B(-1,22,8,minecraft:stone)
B(-1,22,9,minecraft:stone)
B(-1,22,10,minecraft:stone)
B(-1,22,11,minecraft:grass_block)
B(-1,22,12,minecraft:grass_block)
B(-1,23,-10,minecraft:grass_block)
B(-1,23,-9,minecraft:stone)
B(-1,23,-8,minecraft:stone)
B(-1,23,-7,minecraft:stone)
B(-1,23,-6,minecraft:stone)
B(-1,23,-5,minecraft:stone)
B(-1,23,-4,minecraft:stone)
B(-1,23,-3,minecraft:stone)
B(-1,23,-2,minecraft:stone)
B(-1,23,-1,minecraft:stone)
B(-1,23,0,minecraft:stone)
B(-1,23,1,minecraft:stone)
B(-1,23,2,minecraft:stone)
B(-1,23,3,minecraft:stone)
B(-1,23,4,minecraft:stone)
B(-1,23,5,minecraft:stone)
B(-1,23,6,minecraft:stone)
B(-1,23,7,minecraft:stone)
B(-1,23,8,minecraft:stone)
B(-1,23,9,minecraft:stone)
B(-1,23,10,minecraft:stone)
B(-1,24,-9,minecraft:stone)
B(-1,24,-8,minecraft:stone)
B(-1,24,-7,minecraft:stone)
B(-1,24,-6,minecraft:stone)
B(-1,24,-5,minecraft:stone)
B(-1,24,-4,minecraft:stone)
B(-1,24,-3,minecraft:stone)
B(-1,24,-2,minecraft:stone)
B(-1,24,-1,minecraft:stone)
B(-1,24,0,minecraft:stone)
B(-1,24,1,minecraft:stone)
B(-1,24,2,minecraft:stone)
B(-1,24,3,minecraft:stone)
B(-1,24,4,minecraft:stone)
B(-1,24,5,minecraft:stone)
B(-1,24,6,minecraft:stone)
B(-1,24,7,minecraft:stone)
B(-1,24,8,minecraft:stone)
B(-1,24,9,minecraft:stone)
B(-1,24,10,minecraft:stone)
B(-1,25,-9,minecraft:stone)
B(-1,25,-8,minecraft:stone)
B(-1,25,-7,minecraft:stone)
B(-1,25,-6,minecraft:stone)
B(-1,25,-5,minecraft:stone)
B(-1,25,-4,minecraft:stone)
B(-1,25,-3,minecraft:stone)
B(-1,25,-2,minecraft:stone)
B(-1,25,-1,minecraft:stone)
B(-1,25,0,minecraft:stone)
B(-1,25,1,minecraft:stone)
B(-1,25,2,minecraft:stone)
B(-1,25,3,minecraft:stone)
B(-1,25,4,minecraft:stone)
B(-1,25,5,minecraft:stone)
B(-1,25,6,minecraft:stone)
B(-1,25,7,minecraft:stone)
B(-1,25,8,minecraft:stone)
B(-1,25,9,minecraft:stone)
B(-1,25,10,minecraft:stone)
B(-1,26,-9,minecraft:grass_block)
B(-1,26,-8,minecraft:stone)
B(-1,26,-7,minecraft:stone)
B(-1,26,-6,minecraft:stone)
B(-1,26,-5,minecraft:stone)
B(-1,26,-4,minecraft:stone)
B(-1,26,-3,minecraft:stone)
B(-1,26,-2,minecraft:stone)
B(-1,26,-1,minecraft:stone)
B(-1,26,0,minecraft:stone)
B(-1,26,1,minecraft:stone)
B(-1,26,2,minecraft:stone)
B(-1,26,3,minecraft:stone)
B(-1,26,4,minecraft:stone)
B(-1,26,5,minecraft:stone)
B(-1,26,6,minecraft:stone)
B(-1,26,7,minecraft:stone)
B(-1,26,8,minecraft:stone)
B(-1,26,9,minecraft:stone)
B(-1,26,10,minecraft:grass_block)
B(-1,27,-8,minecraft:stone)
B(-1,27,-7,minecraft:stone)
B(-1,27,-6,minecraft:stone)
B(-1,27,-5,minecraft:stone)
B(-1,27,-4,minecraft:stone)
B(-1,27,-3,minecraft:stone)
B(-1,27,-2,minecraft:stone)
B(-1,27,-1,minecraft:stone)
B(-1,27,0,minecraft:stone)
B(-1,27,1,minecraft:stone)
B(-1,27,2,minecraft:stone)
B(-1,27,3,minecraft:stone)
B(-1,27,4,minecraft:stone)
B(-1,27,5,minecraft:stone)
B(-1,27,6,minecraft:stone)
B(-1,27,7,minecraft:stone)
B(-1,27,8,minecraft:stone)
B(-1,27,9,minecraft:stone)
B(-1,28,-8,minecraft:grass_block)
B(-1,28,-7,minecraft:grass_block)
B(-1,28,-6,minecraft:stone)
B(-1,28,-5,minecraft:stone)
B(-1,28,-4,minecraft:stone)
B(-1,28,-3,minecraft:stone)
B(-1,28,-2,minecraft:stone)
B(-1,28,-1,minecraft:cobblestone_wall)
B(-1,28,0,minecraft:rail[shape=east_west])
B(-1,28,2,minecraft:rail[shape=east_west])
B(-1,28,3,minecraft:cobblestone_wall)
B(-1,28,4,minecraft:stone)
B(-1,28,5,minecraft:stone)
B(-1,28,6,minecraft:stone)
B(-1,28,7,minecraft:stone)
B(-1,28,8,minecraft:stone)
B(-1,28,9,minecraft:stone)
B(-1,29,-6,minecraft:grass_block)
B(-1,29,-5,minecraft:stone)
B(-1,29,-4,minecraft:stone)
B(-1,29,-3,minecraft:stone)
B(-1,29,-2,minecraft:stone)
B(-1,29,-1,minecraft:cobblestone_wall)
B(-1,29,3,minecraft:cobblestone_wall)
B(-1,29,4,minecraft:stone)
B(-1,29,5,minecraft:stone)
B(-1,29,6,minecraft:stone)
B(-1,29,7,minecraft:stone)
B(-1,29,8,minecraft:stone)
B(-1,29,9,minecraft:stone)
B(-1,30,-5,minecraft:grass_block)
B(-1,30,-4,minecraft:stone)
B(-1,30,-3,minecraft:stone)
B(-1,30,-2,minecraft:stone)
B(-1,30,-1,minecraft:spruce_log[axis=z])
B(-1,30,0,minecraft:spruce_log[axis=z])
B(-1,30,1,minecraft:spruce_log[axis=z])
B(-1,30,2,minecraft:spruce_log[axis=z])
B(-1,30,3,minecraft:spruce_log[axis=z])
B(-1,30,4,minecraft:stone)
B(-1,30,5,minecraft:stone)
B(-1,30,6,minecraft:stone)
B(-1,30,7,minecraft:stone)
B(-1,30,8,minecraft:stone)
B(-1,30,9,minecraft:stone)
B(-1,31,-4,minecraft:grass_block)
B(-1,31,-3,minecraft:grass_block)
B(-1,31,-2,minecraft:stone)
B(-1,31,1,minecraft:stone)
B(-1,31,2,minecraft:stone)
B(-1,31,3,minecraft:stone)
B(-1,31,4,minecraft:grass_block)
B(-1,31,5,minecraft:stone)
B(-1,31,6,minecraft:grass_block)
B(-1,31,7,minecraft:stone)
B(-1,31,8,minecraft:stone)
B(-1,31,9,minecraft:grass_block)
B(-1,32,5,minecraft:grass_block)
B(-1,32,7,minecraft:grass_block)
B(-1,32,8,minecraft:grass_block)
B(0,3,-6,minecraft:air)
B(0,3,-5,minecraft:air)
B(0,3,-4,minecraft:air)
B(0,3,-3,minecraft:air)
B(0,3,-2,minecraft:air)
B(0,3,-1,minecraft:air)
B(0,3,0,minecraft:air)
B(0,3,1,minecraft:air)
B(0,3,2,minecraft:air)
B(0,3,3,minecraft:air)
B(0,3,4,minecraft:air)
B(0,4,-6,minecraft:air)
B(0,4,-5,minecraft:air)
B(0,4,-4,minecraft:air)
B(0,4,-3,minecraft:air)
B(0,4,-2,minecraft:air)
B(0,4,-1,minecraft:air)
B(0,4,0,minecraft:air)
B(0,4,1,minecraft:air)
B(0,4,2,minecraft:air)
B(0,4,3,minecraft:air)
B(0,4,4,minecraft:air)
B(0,5,-7,minecraft:air)
B(0,5,-6,minecraft:air)
B(0,5,-5,minecraft:air)
B(0,5,-4,minecraft:air)
B(0,5,-3,minecraft:air)
B(0,5,-2,minecraft:air)
B(0,5,-1,minecraft:air)
B(0,5,0,minecraft:air)
B(0,5,1,minecraft:air)
B(0,5,2,minecraft:air)
B(0,5,3,minecraft:air)
B(0,5,4,minecraft:air)
B(0,6,-6,minecraft:air)
B(0,6,-5,minecraft:air)
B(0,6,-4,minecraft:air)
B(0,6,-3,minecraft:air)
B(0,6,-1,minecraft:spruce_log[axis=x])
B(0,6,1,minecraft:air)
B(0,6,2,minecraft:air)
B(0,11,-5,minecraft:spruce_log[axis=x])
B(0,11,-1,minecraft:spruce_log[axis=x])
B(0,12,-4,minecraft:stone)
B(0,12,-2,minecraft:stone)
B(0,13,-4,minecraft:stone)
B(0,13,-3,minecraft:stone)
B(0,13,-2,minecraft:stone)
B(0,14,-4,minecraft:rail[shape=ascending_west])
B(0,14,-3,minecraft:cobblestone_stairs[facing=west,half=bottom,shape=straight,waterlogged=false])
B(0,14,-2,minecraft:rail[shape=ascending_west])
B(0,15,-5,minecraft:oak_fence)
B(0,15,-4,minecraft:air)
B(0,15,-3,minecraft:air)
B(0,15,-2,minecraft:air)
B(0,15,-1,minecraft:oak_fence)
B(0,16,-5,minecraft:spruce_log[axis=x])
B(0,16,-4,minecraft:air)
B(0,16,-3,minecraft:air)
B(0,16,-2,minecraft:air)
B(0,16,-1,minecraft:spruce_log[axis=x])
B(0,17,-5,minecraft:oak_fence)
B(0,17,-4,minecraft:air)
B(0,17,-3,minecraft:air)
B(0,17,-2,minecraft:air)
B(0,17,-1,minecraft:oak_fence)
B(0,22,-11,minecraft:grass_block)
B(0,22,-10,minecraft:grass_block)
B(0,22,-9,minecraft:stone)
B(0,22,-8,minecraft:stone)
B(0,22,-7,minecraft:stone)
B(0,22,-6,minecraft:stone)
B(0,22,-5,minecraft:stone)
B(0,22,-4,minecraft:stone)
B(0,22,-3,minecraft:stone)
B(0,22,-2,minecraft:stone)
B(0,22,-1,minecraft:stone)
B(0,22,0,minecraft:stone)
B(0,22,1,minecraft:stone)
B(0,22,2,minecraft:stone)
B(0,22,3,minecraft:stone)
B(0,22,4,minecraft:stone)
B(0,22,5,minecraft:stone)
B(0,22,6,minecraft:stone)
B(0,22,7,minecraft:stone)
B(0,22,8,minecraft:stone)
B(0,22,9,minecraft:stone)
B(0,22,10,minecraft:grass_block)
B(0,22,11,minecraft:grass_block)
B(0,22,12,minecraft:grass_block)
B(0,23,-9,minecraft:stone)
B(0,23,-8,minecraft:stone)
B(0,23,-7,minecraft:stone)
B(0,23,-6,minecraft:stone)
B(0,23,-5,minecraft:stone)
B(0,23,-4,minecraft:stone)
B(0,23,-3,minecraft:stone)
B(0,23,-2,minecraft:stone)
B(0,23,-1,minecraft:stone)
B(0,23,0,minecraft:stone)
B(0,23,1,minecraft:stone)
B(0,23,2,minecraft:stone)
B(0,23,3,minecraft:stone)
B(0,23,4,minecraft:stone)
B(0,23,5,minecraft:stone)
B(0,23,6,minecraft:stone)
B(0,23,7,minecraft:stone)
B(0,23,8,minecraft:stone)
B(0,23,9,minecraft:stone)
B(0,24,-9,minecraft:grass_block)
B(0,24,-8,minecraft:stone)
B(0,24,-7,minecraft:stone)
B(0,24,-6,minecraft:stone)
B(0,24,-5,minecraft:stone)
B(0,24,-4,minecraft:stone)
B(0,24,-3,minecraft:stone)
B(0,24,-2,minecraft:stone)
B(0,24,-1,minecraft:stone)
B(0,24,0,minecraft:stone)
B(0,24,1,minecraft:stone)
B(0,24,2,minecraft:stone)
B(0,24,3,minecraft:stone)
B(0,24,4,minecraft:stone)
B(0,24,5,minecraft:stone)
B(0,24,6,minecraft:stone)
B(0,24,7,minecraft:stone)
B(0,24,8,minecraft:stone)
B(0,24,9,minecraft:stone)
B(0,25,-8,minecraft:grass_block)
B(0,25,-7,minecraft:stone)
B(0,25,-6,minecraft:stone)
B(0,25,-5,minecraft:stone)
B(0,25,-4,minecraft:stone)
B(0,25,-3,minecraft:stone)
B(0,25,-2,minecraft:stone)
B(0,25,-1,minecraft:stone)
B(0,25,0,minecraft:stone)
B(0,25,1,minecraft:stone)
B(0,25,2,minecraft:stone)
B(0,25,3,minecraft:stone)
B(0,25,4,minecraft:stone)
B(0,25,5,minecraft:stone)
B(0,25,6,minecraft:stone)
B(0,25,7,minecraft:stone)
B(0,25,8,minecraft:stone)
B(0,25,9,minecraft:grass_block)
B(0,26,-7,minecraft:stone)
B(0,26,-6,minecraft:stone)
B(0,26,-5,minecraft:stone)
B(0,26,-4,minecraft:stone)
B(0,26,-3,minecraft:stone)
B(0,26,-2,minecraft:stone)
B(0,26,-1,minecraft:stone)
B(0,26,0,minecraft:stone)
B(0,26,1,minecraft:stone)
B(0,26,2,minecraft:stone)
B(0,26,3,minecraft:stone)
B(0,26,4,minecraft:stone)
B(0,26,5,minecraft:stone)
B(0,26,6,minecraft:stone)
B(0,26,7,minecraft:stone)
B(0,26,8,minecraft:stone)
B(0,27,-7,minecraft:stone)
B(0,27,-6,minecraft:stone)
B(0,27,-5,minecraft:stone)
B(0,27,-4,minecraft:stone)
B(0,27,-3,minecraft:stone)
B(0,27,-2,minecraft:stone)
B(0,27,-1,minecraft:stone)
B(0,27,0,minecraft:stone)
B(0,27,1,minecraft:stone)
B(0,27,2,minecraft:stone)
B(0,27,3,minecraft:stone)
B(0,27,4,minecraft:stone)
B(0,27,5,minecraft:stone)
B(0,27,6,minecraft:stone)
B(0,27,7,minecraft:stone)
B(0,27,8,minecraft:stone)
B(0,28,-7,minecraft:grass_block)
B(0,28,-6,minecraft:stone)
B(0,28,-5,minecraft:stone)
B(0,28,-4,minecraft:stone)
B(0,28,-3,minecraft:stone)
B(0,28,-2,minecraft:stone)
B(0,28,-1,minecraft:cobblestone_stairs[facing=west,half=bottom,shape=straight,waterlogged=false])
B(0,28,0,minecraft:rail[shape=east_west])
B(0,28,2,minecraft:rail[shape=east_west])
B(0,28,3,minecraft:cobblestone_stairs[facing=west,half=bottom,shape=straight,waterlogged=false])
B(0,28,4,minecraft:stone)
B(0,28,5,minecraft:stone)
B(0,28,6,minecraft:stone)
B(0,28,7,minecraft:stone)
B(0,28,8,minecraft:stone)
B(0,29,-6,minecraft:grass_block)
B(0,29,-5,minecraft:grass_block)
B(0,29,-4,minecraft:stone)
B(0,29,-3,minecraft:stone)
B(0,29,-2,minecraft:stone)
B(0,29,4,minecraft:stone)
B(0,29,5,minecraft:stone)
B(0,29,6,minecraft:stone)
B(0,29,7,minecraft:stone)
B(0,29,8,minecraft:stone)
B(0,30,-4,minecraft:grass_block)
B(0,30,-3,minecraft:stone)
B(0,30,-2,minecraft:stone)
B(0,30,4,minecraft:stone)
B(0,30,5,minecraft:stone)
B(0,30,6,minecraft:stone)
B(0,30,7,minecraft:stone)
B(0,30,8,minecraft:grass_block)
B(0,31,-3,minecraft:grass_block)
B(0,31,-2,minecraft:stone)
B(0,31,4,minecraft:grass_block)
B(0,31,5,minecraft:stone)
B(0,31,6,minecraft:grass_block)
B(0,31,7,minecraft:infested_cobblestone)
B(0,32,5,minecraft:grass_block)
B(0,32,7,minecraft:infested_cobblestone)
B(0,33,7,minecraft:cobblestone_stairs[facing=east,half=bottom,shape=straight,waterlogged=false])
B(1,3,-6,minecraft:air)
B(1,3,-5,minecraft:air)
B(1,3,-4,minecraft:air)
B(1,3,-3,minecraft:air)
B(1,3,-2,minecraft:air)
B(1,3,-1,minecraft:air)
B(1,3,0,minecraft:air)
B(1,3,1,minecraft:air)
B(1,3,2,minecraft:air)
B(1,3,3,minecraft:air)
B(1,4,-7,minecraft:air)
B(1,4,-6,minecraft:air)
B(1,4,-5,minecraft:air)
B(1,4,-4,minecraft:air)
B(1,4,-3,minecraft:air)
B(1,4,-2,minecraft:air)
B(1,4,-1,minecraft:air)
B(1,4,0,minecraft:air)
B(1,4,1,minecraft:air)
B(1,4,2,minecraft:air)
B(1,4,3,minecraft:air)
B(1,4,4,minecraft:air)
B(1,5,-7,minecraft:air)
B(1,5,-6,minecraft:air)
B(1,5,-5,minecraft:air)
B(1,5,-4,minecraft:air)
B(1,5,-3,minecraft:air)
B(1,5,-2,minecraft:air)
B(1,5,-1,minecraft:air)
B(1,5,0,minecraft:air)
B(1,5,1,minecraft:air)
B(1,5,2,minecraft:air)
B(1,5,3,minecraft:air)
B(1,5,4,minecraft:air)
B(1,6,-6,minecraft:air)
B(1,6,-5,minecraft:air)
B(1,6,-4,minecraft:air)
B(1,6,-1,minecraft:spruce_log[axis=x])
B(1,6,1,minecraft:air)
B(1,10,-3,minecraft:stone)
B(1,11,-5,minecraft:spruce_log[axis=x])
B(1,11,-4,minecraft:stone)
B(1,11,-3,minecraft:stone)
B(1,11,-2,minecraft:stone)
B(1,11,-1,minecraft:spruce_log[axis=x])
B(1,12,-4,minecraft:stone)
B(1,12,-3,minecraft:stone)
B(1,12,-2,minecraft:stone)
B(1,13,-4,minecraft:rail[shape=ascending_west])
B(1,13,-3,minecraft:cobblestone_stairs[facing=west,half=bottom,shape=straight,waterlogged=false])
B(1,13,-2,minecraft:rail[shape=ascending_west])
B(1,14,-5,minecraft:oak_fence)
B(1,14,-4,minecraft:air)
B(1,14,-3,minecraft:air)
B(1,14,-2,minecraft:air)
B(1,15,-5,minecraft:oak_fence)
B(1,15,-4,minecraft:air)
B(1,15,-3,minecraft:air)
B(1,15,-2,minecraft:air)
B(1,15,-1,minecraft:oak_fence)
B(1,16,-5,minecraft:spruce_log[axis=x])
B(1,16,-4,minecraft:air)
B(1,16,-3,minecraft:wall_torch[facing=west])
B(1,16,-2,minecraft:air)
B(1,16,-1,minecraft:spruce_log[axis=x])
B(1,22,-11,minecraft:grass_block)
B(1,22,-10,minecraft:grass_block)
B(1,22,-9,minecraft:grass_block)
B(1,22,-8,minecraft:stone)
B(1,22,-7,minecraft:stone)
B(1,22,-6,minecraft:stone)
B(1,22,-5,minecraft:stone)
B(1,22,-4,minecraft:stone)
B(1,22,-3,minecraft:stone)
B(1,22,-2,minecraft:stone)
B(1,22,-1,minecraft:stone)
B(1,22,0,minecraft:stone)
B(1,22,1,minecraft:stone)
B(1,22,2,minecraft:stone)
B(1,22,3,minecraft:stone)
B(1,22,4,minecraft:stone)
B(1,22,5,minecraft:stone)
B(1,22,6,minecraft:stone)
B(1,22,7,minecraft:stone)
B(1,22,8,minecraft:stone)
B(1,22,9,minecraft:stone)
B(1,22,10,minecraft:stone)
B(1,22,11,minecraft:grass_block)
B(1,22,12,minecraft:grass_block)
B(1,23,-8,minecraft:grass_block)
B(1,23,-7,minecraft:stone)
B(1,23,-6,minecraft:stone)
B(1,23,-5,minecraft:stone)
B(1,23,-4,minecraft:stone)
B(1,23,-3,minecraft:stone)
B(1,23,-2,minecraft:stone)
B(1,23,-1,minecraft:stone)
B(1,23,0,minecraft:stone)
B(1,23,1,minecraft:stone)
B(1,23,2,minecraft:stone)
B(1,23,3,minecraft:stone)
B(1,23,4,minecraft:stone)
B(1,23,5,minecraft:stone)
B(1,23,6,minecraft:stone)
B(1,23,7,minecraft:stone)
B(1,23,8,minecraft:stone)
B(1,23,9,minecraft:stone)
B(1,23,10,minecraft:stone)
B(1,24,-7,minecraft:grass_block)
B(1,24,-6,minecraft:stone)
B(1,24,-5,minecraft:stone)
B(1,24,-4,minecraft:stone)
B(1,24,-3,minecraft:stone)
B(1,24,-2,minecraft:stone)
B(1,24,-1,minecraft:stone)
B(1,24,0,minecraft:stone)
B(1,24,1,minecraft:stone)
B(1,24,2,minecraft:stone)
B(1,24,3,minecraft:stone)
B(1,24,4,minecraft:stone)
B(1,24,5,minecraft:stone)
B(1,24,6,minecraft:stone)
B(1,24,7,minecraft:stone)
B(1,24,8,minecraft:stone)
B(1,24,9,minecraft:stone)
B(1,24,10,minecraft:stone)
B(1,25,-6,minecraft:stone)
B(1,25,-5,minecraft:stone)
B(1,25,-4,minecraft:stone)
B(1,25,-3,minecraft:stone)
B(1,25,-2,minecraft:stone)
B(1,25,-1,minecraft:stone)
B(1,25,0,minecraft:stone)
B(1,25,1,minecraft:stone)
B(1,25,2,minecraft:stone)
B(1,25,3,minecraft:stone)
B(1,25,4,minecraft:stone)
B(1,25,5,minecraft:stone)
B(1,25,6,minecraft:stone)
B(1,25,7,minecraft:stone)
B(1,25,8,minecraft:stone)
B(1,25,9,minecraft:stone)
B(1,25,10,minecraft:stone)
B(1,26,-6,minecraft:stone)
B(1,26,-5,minecraft:stone)
B(1,26,-4,minecraft:stone)
B(1,26,-3,minecraft:stone)
B(1,26,-2,minecraft:stone)
B(1,26,-1,minecraft:stone)
B(1,26,0,minecraft:stone)
B(1,26,1,minecraft:stone)
B(1,26,2,minecraft:stone)
B(1,26,3,minecraft:stone)
B(1,26,4,minecraft:stone)
B(1,26,5,minecraft:stone)
B(1,26,6,minecraft:stone)
B(1,26,7,minecraft:stone)
B(1,26,8,minecraft:stone)
B(1,26,9,minecraft:stone)
B(1,26,10,minecraft:stone)
B(1,27,-6,minecraft:grass_block)
B(1,27,-5,minecraft:stone)
B(1,27,-4,minecraft:stone)
B(1,27,-3,minecraft:stone)
B(1,27,-2,minecraft:stone)
B(1,27,-1,minecraft:stone)
B(1,27,0,minecraft:stone)
B(1,27,1,minecraft:stone)
B(1,27,2,minecraft:stone)
B(1,27,3,minecraft:stone)
B(1,27,4,minecraft:stone)
B(1,27,5,minecraft:stone)
B(1,27,6,minecraft:stone)
B(1,27,7,minecraft:stone)
B(1,27,8,minecraft:stone)
B(1,27,9,minecraft:stone)
B(1,27,10,minecraft:grass_block)
B(1,28,-5,minecraft:grass_block)
B(1,28,-4,minecraft:stone)
B(1,28,-3,minecraft:stone)
B(1,28,-2,minecraft:stone)
B(1,28,0,minecraft:rail[shape=east_west])
B(1,28,2,minecraft:rail[shape=east_west])
B(1,28,4,minecraft:stone)
B(1,28,5,minecraft:infested_cobblestone)
B(1,28,6,minecraft:stone)
B(1,28,7,minecraft:stone)
B(1,28,8,minecraft:stone)
B(1,28,9,minecraft:infested_cobblestone)
B(1,29,-4,minecraft:stone)
B(1,29,-2,minecraft:stone)
B(1,29,5,minecraft:cobblestone_stairs[facing=south,half=bottom,shape=straight,waterlogged=false])
B(1,29,6,minecraft:infested_cobblestone)
B(1,29,7,minecraft:infested_cobblestone)
B(1,29,8,minecraft:infested_cobblestone)
B(1,29,9,minecraft:cobblestone_stairs)
B(1,30,-4,minecraft:grass_block)
B(1,30,6,minecraft:infested_cobblestone)
B(1,30,7,minecraft:infested_cobblestone)
B(1,30,8,minecraft:infested_cobblestone)
B(1,31,6,minecraft:infested_cobblestone)
B(1,31,7,minecraft:infested_cobblestone)
B(1,31,8,minecraft:infested_cobblestone)
B(1,32,6,minecraft:infested_cobblestone)
B(1,32,7,minecraft:infested_cobblestone)
B(1,32,8,minecraft:infested_cobblestone)
B(1,33,6,minecraft:cobblestone_stairs[facing=south,half=bottom,shape=straight,waterlogged=false])
B(1,33,7,minecraft:infested_cobblestone)
B(1,33,8,minecraft:cobblestone_stairs[facing=east,half=bottom,shape=straight,waterlogged=false])
B(1,34,7,minecraft:infested_cobblestone)
B(1,35,7,minecraft:infested_cobblestone)
B(1,36,7,minecraft:infested_cobblestone)
B(1,37,7,minecraft:infested_cobblestone)
B(1,38,7,minecraft:infested_cobblestone)
B(1,39,7,minecraft:cobblestone_wall)
B(2,3,-7,minecraft:air)
B(2,3,-6,minecraft:air)
B(2,3,-5,minecraft:air)
B(2,3,-4,minecraft:air)
B(2,3,-3,minecraft:air)
B(2,3,-2,minecraft:air)
B(2,3,-1,minecraft:air)
B(2,3,0,minecraft:air)
B(2,3,1,minecraft:air)
B(2,4,-7,minecraft:air)
B(2,4,-6,minecraft:air)
B(2,4,-5,minecraft:air)
B(2,4,-4,minecraft:air)
B(2,4,-3,minecraft:air)
B(2,4,-2,minecraft:air)
B(2,4,-1,minecraft:air)
B(2,4,0,minecraft:air)
B(2,4,1,minecraft:air)
B(2,5,-7,minecraft:air)
B(2,5,-6,minecraft:air)
B(2,5,-5,minecraft:air)
B(2,5,-4,minecraft:air)
B(2,5,-3,minecraft:air)
B(2,5,-2,minecraft:air)
B(2,5,-1,minecraft:air)
B(2,5,0,minecraft:air)
B(2,5,1,minecraft:air)
B(2,6,-5,minecraft:air)
B(2,6,-4,minecraft:air)
B(2,6,-1,minecraft:spruce_log[axis=x])
B(2,9,-4,minecraft:stone)
B(2,10,-4,minecraft:stone)
B(2,10,-3,minecraft:stone)
B(2,10,-2,minecraft:stone)
B(2,11,-5,minecraft:spruce_log[axis=x])
B(2,11,-4,minecraft:stone)
B(2,11,-3,minecraft:stone)
B(2,11,-2,minecraft:stone)
B(2,11,-1,minecraft:spruce_log[axis=x])
B(2,12,-5,minecraft:spruce_log)
B(2,12,-4,minecraft:rail[shape=ascending_west])
B(2,12,-3,minecraft:cobblestone_stairs[facing=west,half=bottom,shape=straight,waterlogged=false])
B(2,12,-2,minecraft:rail[shape=ascending_west])
B(2,12,-1,minecraft:spruce_log)
B(2,13,-5,minecraft:spruce_log)
B(2,13,-4,minecraft:air)
B(2,13,-3,minecraft:air)
B(2,13,-2,minecraft:air)
B(2,13,-1,minecraft:spruce_log)
B(2,14,-5,minecraft:spruce_log)
B(2,14,-4,minecraft:air)
B(2,14,-3,minecraft:air)
B(2,14,-2,minecraft:air)
B(2,14,-1,minecraft:spruce_log)
B(2,15,-5,minecraft:spruce_log)
B(2,15,-4,minecraft:air)
B(2,15,-3,minecraft:air)
B(2,15,-2,minecraft:air)
B(2,15,-1,minecraft:spruce_log)
B(2,16,-5,minecraft:spruce_log[axis=z])
B(2,16,-4,minecraft:spruce_log[axis=z])
B(2,16,-3,minecraft:spruce_log[axis=z])
B(2,16,-2,minecraft:spruce_log[axis=z])
B(2,16,-1,minecraft:spruce_log[axis=x])
